Workbook

Sheet V-FTE Mar
A1: LOCK | B1: 46082 | C1: =B1+1 -> 46083 | D1: =C1+1 -> 46084 | E1: =D1+1 -> 46085 | F1: =E1+1 -> 46086 | G1: =F1+1 -> 46087 | H1: =G1+1 -> 46088 | I1: =H1+1 -> 46089 | J1: =I1+1 -> 46090 | ... AF1: =AE1+1 -> 46112 | AI1: MAX REQUIRED FTE
B2: =TEXT(B1,"ddd") -> Sun | C2: =TEXT(C1,"ddd") -> Mon | D2: =TEXT(D1,"ddd") -> Tue | E2: =TEXT(E1,"ddd") -> Wed | F2: =TEXT(F1,"ddd") -> Thu | G2: =TEXT(G1,"ddd") -> Fri | H2: =TEXT(H1,"ddd") -> Sat | I2: =TEXT(I1,"ddd") -> Sun | ... AF2: =TEXT(AF1,"ddd") -> Tue | AI2: Mon | AJ2: Tue | AK2: Wed | AL2: Thu | AM2: Fri | AN2: Sat | AO2: Sun
A3: 12:00 AM | B3: 0 | C3: 0 | D3: 0 | E3: 0 | F3: 0 | G3: 0 | H3: 0 | I3: 0 | J3: 0 | K3: 0 | L3: 0 | M3: 0 | N3: 0 | O3: 0 | P3: 0 | Q3: 0 | R3: 0 | S3: 0 | T3: 0 | U3: 0 | V3: 0 | W3: 0 | X3: 0 | Y3: 0 | Z3: 0 | AA3: 0 | AB3: 0 | AC3: 0 | AD3: 0 | AE3: 0 | AF3: 0
A4: 12:30 AM | B4: 0 | C4: 0 | D4: 0 | E4: 0 | F4: 0 | G4: 0 | H4: 0 | I4: 0 | J4: 0 | K4: 0 | L4: 0 | M4: 0 | N4: 0 | O4: 0 | P4: 0 | Q4: 0 | R4: 0 | S4: 0 | T4: 0 | U4: 0 | V4: 0 | W4: 0 | X4: 0 | Y4: 0 | Z4: 0 | AA4: 0 | AB4: 0 | AC4: 0 | AD4: 0 | AE4: 0 | AF4: 0
A5: 1:00 AM | B5: 0 | C5: 0 | D5: 0 | E5: 0 | F5: 0 | G5: 0 | H5: 0 | I5: 0 | J5: 0 | K5: 0 | L5: 0 | M5: 0 | N5: 0 | O5: 0 | P5: 0 | Q5: 0 | R5: 0 | S5: 0 | T5: 0 | U5: 0 | V5: 0 | W5: 0 | X5: 0 | Y5: 0 | Z5: 0 | AA5: 0 | AB5: 0 | AC5: 0 | AD5: 0 | AE5: 0 | AF5: 0
A6: 1:30 AM | B6: 0 | C6: 0 | D6: 0 | E6: 0 | F6: 0 | G6: 0 | H6: 0 | I6: 0 | J6: 0 | K6: 0 | L6: 0 | M6: 0 | N6: 0 | O6: 0 | P6: 0 | Q6: 0 | R6: 0 | S6: 0 | T6: 0 | U6: 0 | V6: 0 | W6: 0 | X6: 0 | Y6: 0 | Z6: 0 | AA6: 0 | AB6: 0 | AC6: 0 | AD6: 0 | AE6: 0 | AF6: 0
A7: 2:00 AM | B7: 0 | C7: 0 | D7: 0 | E7: 0 | F7: 0 | G7: 0 | H7: 0 | I7: 0 | J7: 0 | K7: 0 | L7: 0 | M7: 0 | N7: 0 | O7: 0 | P7: 0 | Q7: 0 | R7: 0 | S7: 0 | T7: 0 | U7: 0 | V7: 0 | W7: 0 | X7: 0 | Y7: 0 | Z7: 0 | AA7: 0 | AB7: 0 | AC7: 0 | AD7: 0 | AE7: 0 | AF7: 0
A8: 2:30 AM | B8: 0 | C8: 0 | D8: 0 | E8: 0 | F8: 0 | G8: 0 | H8: 0 | I8: 0 | J8: 0 | K8: 0 | L8: 0 | M8: 0 | N8: 0 | O8: 0 | P8: 0 | Q8: 0 | R8: 0 | S8: 0 | T8: 0 | U8: 0 | V8: 0 | W8: 0 | X8: 0 | Y8: 0 | Z8: 0 | AA8: 0 | AB8: 0 | AC8: 0 | AD8: 0 | AE8: 0 | AF8: 0
A9: 3:00 AM | B9: 0 | C9: 0 | D9: 0 | E9: 0 | F9: 0 | G9: 0 | H9: 0 | I9: 0 | J9: 0 | K9: 0 | L9: 0 | M9: 0 | N9: 0 | O9: 0 | P9: 0 | Q9: 0 | R9: 0 | S9: 0 | T9: 0 | U9: 0 | V9: 0 | W9: 0 | X9: 0 | Y9: 0 | Z9: 0 | AA9: 0 | AB9: 0 | AC9: 0 | AD9: 0 | AE9: 0 | AF9: 0
A10: 3:30 AM | B10: 0 | C10: 0 | D10: 0 | E10: 0 | F10: 0 | G10: 0 | H10: 0 | I10: 0 | J10: 0 | K10: 0 | L10: 0 | M10: 0 | N10: 0 | O10: 0 | P10: 0 | Q10: 0 | R10: 0 | S10: 0 | T10: 0 | U10: 0 | V10: 0 | W10: 0 | X10: 0 | Y10: 0 | Z10: 0 | AA10: 0 | AB10: 0 | AC10: 0 | AD10: 0 | AE10: 0 | AF10: 0
A11: 4:00 AM | B11: 0 | C11: 0 | D11: 0 | E11: 0 | F11: 0 | G11: 0 | H11: 0 | I11: 0 | J11: 0 | K11: 0 | L11: 0 | M11: 0 | N11: 0 | O11: 0 | P11: 0 | Q11: 0 | R11: 0 | S11: 0 | T11: 0 | U11: 0 | V11: 0 | W11: 0 | X11: 0 | Y11: 0 | Z11: 0 | AA11: 0 | AB11: 0 | AC11: 0 | AD11: 0 | AE11: 0 | AF11: 0
A12: 4:30 AM | B12: 0 | C12: 0 | D12: 0 | E12: 0 | F12: 0 | G12: 0 | H12: 0 | I12: 0 | J12: 0 | K12: 0 | L12: 0 | M12: 0 | N12: 0 | O12: 0 | P12: 0 | Q12: 0 | R12: 0 | S12: 0 | T12: 0 | U12: 0 | V12: 0 | W12: 0 | X12: 0 | Y12: 0 | Z12: 0 | AA12: 0 | AB12: 0 | AC12: 0 | AD12: 0 | AE12: 0 | AF12: 0
A13: 5:00 AM | B13: 0 | C13: 0 | D13: 0 | E13: 0 | F13: 0 | G13: 0 | H13: 0 | I13: 0 | J13: 0 | K13: 0 | L13: 0 | M13: 0 | N13: 0 | O13: 0 | P13: 0 | Q13: 0 | R13: 0 | S13: 0 | T13: 0 | U13: 0 | V13: 0 | W13: 0 | X13: 0 | Y13: 0 | Z13: 0 | AA13: 0 | AB13: 0 | AC13: 0 | AD13: 0 | AE13: 0 | AF13: 0
A14: 5:30 AM | B14: 0 | C14: 0 | D14: 0 | E14: 0 | F14: 0 | G14: 0 | H14: 0 | I14: 0 | J14: 0 | K14: 0 | L14: 0 | M14: 0 | N14: 0 | O14: 0 | P14: 0 | Q14: 0 | R14: 0 | S14: 0 | T14: 0 | U14: 0 | V14: 0 | W14: 0 | X14: 0 | Y14: 0 | Z14: 0 | AA14: 0 | AB14: 0 | AC14: 0 | AD14: 0 | AE14: 0 | AF14: 0
... A18: 7:30 AM | B18: 0 | C18: 0 | D18: 0 | E18: 0 | F18: 0 | G18: 0 | H18: 0 | I18: 0 | J18: 0 | K18: 0 | L18: 0 | M18: 0 | N18: 0 | O18: 0 | P18: 0 | Q18: 0 | R18: 0 | S18: 0 | T18: 0 | U18: 0 | V18: 0 | W18: 0 | X18: 0 | Y18: 0 | Z18: 0 | AA18: 0 | AB18: 0 | AC18: 0 | AD18: 0 | AE18: 0 | AF18: 0
A19: 8:00 AM | B19: 0 | C19: 8.6267112 | D19: 5.7144456 | E19: 4.3834101 | F19: 5.0038928 | G19: 5.274103 | H19: 0 | I19: 0 | J19: 7.9461818 | K19: 4.4534646 | L19: 4.0731688 | M19: 4.6736359 | N19: 4.6135892 | O19: 0 | P19: 0 | Q19: 7.6059171 | R19: 4.4534646 | S19: 4.3834101 | T19: 4.6736359 | U19: 4.6135892 | V19: 0 | W19: 0 | X19: 7.9461818 | Y19: 4.4534646 | Z19: 4.3834101 | AA19: 4.6736359 | AB19: 4.9438461 | AC19: 0 | AD19: 0 | AE19: 7.9461818 | AF19: 4.7737137 | AI19: {=MAX(_xlfn._xlws.FILTER($D19:$AF19, $D$2:$AF$2=AI$2))} -> 7.9461818 | AJ19: {=MAX(_xlfn._xlws.FILTER($B19:$AF19, $B$2:$AF$2=AJ$2))} -> 5.7144456 | AK19: {=MAX(_xlfn._xlws.FILTER($B19:$AF19, $B$2:$AF$2=AK$2))} -> 4.3834101 | AL19: {=MAX(_xlfn._xlws.FILTER($B19:$AF19, $B$2:$AF$2=AL$2))} -> 5.0038928 | AM19: {=MAX(_xlfn._xlws.FILTER($B19:$AF19, $B$2:$AF$2=AM$2))} -> 5.274103 | AN19: {=MAX(_xlfn._xlws.FILTER($B19:$AF19, $B$2:$AF$2=AN$2))} -> 0 | AO19: {=MAX(_xlfn._xlws.FILTER($B19:$AF19, $B$2:$AF$2=AO$2))} -> 0
A20: 8:30 AM | B20: 0 | C20: 16.472815 | D20: 10.338043 | E20: 8.6867579 | F20: 9.0170149 | G20: 9.3973107 | H20: 0 | I20: 0 | J20: 13.760705 | K20: 7.9661974 | L20: 8.3364854 | M20: 9.0170149 | N20: 8.6567346 | O20: 0 | P20: 0 | Q20: 13.380409 | R20: 7.9661974 | S20: 8.6867579 | T20: 8.6467268 | U20: 8.6567346 | V20: 0 | W20: 0 | X20: 13.760705 | Y20: 8.3064621 | Z20: 9.0470382 | AA20: 9.3873029 | AB20: 9.0270226 | AC20: 0 | AD20: 0 | AE20: 14.541313 | AF20: 8.6467268 | AI20: {=MAX(_xlfn._xlws.FILTER($D20:$AF20, $D$2:$AF$2=AI$2))} -> 14.541313 | AJ20: {=MAX(_xlfn._xlws.FILTER($B20:$AF20, $B$2:$AF$2=AJ$2))} -> 10.338043 | AK20: {=MAX(_xlfn._xlws.FILTER($B20:$AF20, $B$2:$AF$2=AK$2))} -> 9.0470382 | AL20: {=MAX(_xlfn._xlws.FILTER($B20:$AF20, $B$2:$AF$2=AL$2))} -> 9.3873029 | AM20: {=MAX(_xlfn._xlws.FILTER($B20:$AF20, $B$2:$AF$2=AM$2))} -> 9.3973107 | AN20: {=MAX(_xlfn._xlws.FILTER($B20:$AF20, $B$2:$AF$2=AN$2))} -> 0 | AO20: {=MAX(_xlfn._xlws.FILTER($B20:$AF20, $B$2:$AF$2=AO$2))} -> 0
A21: 9:00 AM | B21: 0 | C21: 34.867125 | D21: 22.447463 | E21: 18.144115 | F21: 18.864676 | G21: 19.044816 | H21: 5.7744923 | I21: 0 | J21: 25.559885 | K21: 15.572114 | L21: 15.432005 | M21: 15.77227 | N21: 15.532083 | O21: 4.7536982 | P21: 0 | Q21: 24.749254 | R21: 15.211834 | S21: 15.822309 | T21: 15.381967 | U21: 15.922387 | V21: 4.4134335 | W21: 0 | X21: 25.559885 | Y21: 15.572114 | Z21: 16.592909 | AA21: 16.54287 | AB21: 16.702994 | AC21: 5.0939629 | AD21: 0 | AE21: 26.370515 | AF21: 17.023243 | AI21: {=MAX(_xlfn._xlws.FILTER($D21:$AF21, $D$2:$AF$2=AI$2))} -> 26.370515 | AJ21: {=MAX(_xlfn._xlws.FILTER($B21:$AF21, $B$2:$AF$2=AJ$2))} -> 22.447463 | AK21: {=MAX(_xlfn._xlws.FILTER($B21:$AF21, $B$2:$AF$2=AK$2))} -> 18.144115 | AL21: {=MAX(_xlfn._xlws.FILTER($B21:$AF21, $B$2:$AF$2=AL$2))} -> 18.864676 | AM21: {=MAX(_xlfn._xlws.FILTER($B21:$AF21, $B$2:$AF$2=AM$2))} -> 19.044816 | AN21: {=MAX(_xlfn._xlws.FILTER($B21:$AF21, $B$2:$AF$2=AN$2))} -> 5.7744923 | AO21: {=MAX(_xlfn._xlws.FILTER($B21:$AF21, $B$2:$AF$2=AO$2))} -> 0
A22: 9:30 AM | B22: 0 | C22: 47.797184 | D22: 34.666969 | E22: 31.27433 | F22: 29.933287 | G22: 28.412103 | H22: 9.337264 | I22: 0 | J22: 39.23052 | K22: 24.739246 | L22: 24.418997 | M22: 23.708444 | N22: 23.54832 | O22: 7.4858237 | P22: 0 | Q22: 37.939515 | R22: 23.938623 | S22: 24.849332 | T22: 22.86779 | U22: 23.948631 | V22: 7.1155356 | W22: 0 | X22: 39.23052 | Y22: 24.739246 | Z22: 26.140336 | AA22: 24.53909 | AB22: 25.569892 | AC22: 7.8561117 | AD22: 0 | AE22: 40.511516 | AF22: 26.730795 | AI22: {=MAX(_xlfn._xlws.FILTER($D22:$AF22, $D$2:$AF$2=AI$2))} -> 40.511516 | AJ22: {=MAX(_xlfn._xlws.FILTER($B22:$AF22, $B$2:$AF$2=AJ$2))} -> 34.666969 | AK22: {=MAX(_xlfn._xlws.FILTER($B22:$AF22, $B$2:$AF$2=AK$2))} -> 31.27433 | AL22: {=MAX(_xlfn._xlws.FILTER($B22:$AF22, $B$2:$AF$2=AL$2))} -> 29.933287 | AM22: {=MAX(_xlfn._xlws.FILTER($B22:$AF22, $B$2:$AF$2=AM$2))} -> 28.412103 | AN22: {=MAX(_xlfn._xlws.FILTER($B22:$AF22, $B$2:$AF$2=AN$2))} -> 9.337264 | AO22: {=MAX(_xlfn._xlws.FILTER($B22:$AF22, $B$2:$AF$2=AO$2))} -> 0
A23: 10:00 AM | B23: 0 | C23: 71.185379 | D23: 49.868796 | E23: 43.463813 | F23: 44.354506 | G23: 41.292124 | H23: 14.871569 | I23: 0 | J23: 51.780283 | K23: 33.175809 | L23: 32.515296 | M23: 31.214283 | N23: 31.00412 | O23: 11.699101 | P23: 0 | Q23: 49.518523 | R23: 31.924836 | S23: 32.955638 | T23: 30.333598 | U23: 31.434455 | V23: 11.29879 | W23: 0 | X23: 51.329933 | Y23: 33.175809 | Z23: 34.717008 | AA23: 32.094969 | AB23: 33.576121 | AC23: 12.489716 | AD23: 0 | AE23: 53.131334 | AF23: 35.687764 | AI23: {=MAX(_xlfn._xlws.FILTER($D23:$AF23, $D$2:$AF$2=AI$2))} -> 53.131334 | AJ23: {=MAX(_xlfn._xlws.FILTER($B23:$AF23, $B$2:$AF$2=AJ$2))} -> 49.868796 | AK23: {=MAX(_xlfn._xlws.FILTER($B23:$AF23, $B$2:$AF$2=AK$2))} -> 43.463813 | AL23: {=MAX(_xlfn._xlws.FILTER($B23:$AF23, $B$2:$AF$2=AL$2))} -> 44.354506 | AM23: {=MAX(_xlfn._xlws.FILTER($B23:$AF23, $B$2:$AF$2=AM$2))} -> 41.292124 | AN23: {=MAX(_xlfn._xlws.FILTER($B23:$AF23, $B$2:$AF$2=AN$2))} -> 14.871569 | AO23: {=MAX(_xlfn._xlws.FILTER($B23:$AF23, $B$2:$AF$2=AO$2))} -> 0
A24: 10:30 AM | B24: 0 | C24: 81.193165 | D24: 60.707228 | E24: 51.890369 | F24: 52.881139 | G24: 49.548547 | H24: 20.325813 | I24: 0 | J24: 63.749595 | K24: 42.583128 | L24: 40.401431 | M24: 38.399873 | N24: 38.18971 | O24: 16.052488 | P24: 0 | Q24: 61.447804 | R24: 41.282116 | S24: 40.841773 | T24: 37.519188 | U24: 39.070395 | V24: 16.052488 | W24: 0 | X24: 63.749595 | Y24: 43.013463 | Z24: 43.053494 | AA24: 39.720901 | AB24: 41.692435 | AC24: 17.76382 | AD24: 0 | AE24: 65.581019 | AF24: 46.466149 | AI24: {=MAX(_xlfn._xlws.FILTER($D24:$AF24, $D$2:$AF$2=AI$2))} -> 65.581019 | AJ24: {=MAX(_xlfn._xlws.FILTER($B24:$AF24, $B$2:$AF$2=AJ$2))} -> 60.707228 | AK24: {=MAX(_xlfn._xlws.FILTER($B24:$AF24, $B$2:$AF$2=AK$2))} -> 51.890369 | AL24: {=MAX(_xlfn._xlws.FILTER($B24:$AF24, $B$2:$AF$2=AL$2))} -> 52.881139 | AM24: {=MAX(_xlfn._xlws.FILTER($B24:$AF24, $B$2:$AF$2=AM$2))} -> 49.548547 | AN24: {=MAX(_xlfn._xlws.FILTER($B24:$AF24, $B$2:$AF$2=AN$2))} -> 20.325813 | AO24: {=MAX(_xlfn._xlws.FILTER($B24:$AF24, $B$2:$AF$2=AO$2))} -> 0
A25: 11:00 AM | B25: 0 | C25: 98.096315 | D25: 74.928291 | E25: 66.721907 | F25: 66.501736 | G25: 60.717235 | H25: 26.140336 | I25: 0 | J25: 84.095423 | K25: 55.773389 | L25: 54.442354 | M25: 51.169808 | N25: 49.768718 | O25: 19.455135 | P25: 0 | Q25: 80.822877 | R25: 54.072066 | S25: 55.353062 | T25: 49.418445 | U25: 50.649403 | V25: 19.455135 | W25: 0 | X25: 83.625057 | Y25: 55.773389 | Z25: 58.085188 | AA25: 52.480828 | AB25: 54.152128 | AC25: 21.246529 | AD25: 0 | AE25: 86.897603 | AF25: 60.457033 | AI25: {=MAX(_xlfn._xlws.FILTER($D25:$AF25, $D$2:$AF$2=AI$2))} -> 86.897603 | AJ25: {=MAX(_xlfn._xlws.FILTER($B25:$AF25, $B$2:$AF$2=AJ$2))} -> 74.928291 | AK25: {=MAX(_xlfn._xlws.FILTER($B25:$AF25, $B$2:$AF$2=AK$2))} -> 66.721907 | AL25: {=MAX(_xlfn._xlws.FILTER($B25:$AF25, $B$2:$AF$2=AL$2))} -> 66.501736 | AM25: {=MAX(_xlfn._xlws.FILTER($B25:$AF25, $B$2:$AF$2=AM$2))} -> 60.717235 | AN25: {=MAX(_xlfn._xlws.FILTER($B25:$AF25, $B$2:$AF$2=AN$2))} -> 26.140336 | AO25: {=MAX(_xlfn._xlws.FILTER($B25:$AF25, $B$2:$AF$2=AO$2))} -> 0
A26: 11:30 AM | B26: 0 | C26: 127.31905 | D26: 86.717463 | E26: 77.78051 | F26: 78.14079 | G26: 77.049942 | H26: 30.363622 | I26: 0 | J26: 104.27112 | K26: 68.74348 | L26: 67.272335 | M26: 63.149127 | N26: 61.157578 | O26: 22.50751 | P26: 0 | Q26: 99.757607 | R26: 66.952086 | S26: 68.223075 | T26: 61.267664 | U26: 62.558668 | V26: 22.047152 | W26: 0 | X26: 103.77073 | Y26: 69.19383 | Z26: 72.056057 | AA26: 65.490949 | AB26: 66.771946 | AC26: 24.35895 | AD26: 0 | AE26: 107.28346 | AF26: 75.038377 | AI26: {=MAX(_xlfn._xlws.FILTER($D26:$AF26, $D$2:$AF$2=AI$2))} -> 107.28346 | AJ26: {=MAX(_xlfn._xlws.FILTER($B26:$AF26, $B$2:$AF$2=AJ$2))} -> 86.717463 | AK26: {=MAX(_xlfn._xlws.FILTER($B26:$AF26, $B$2:$AF$2=AK$2))} -> 77.78051 | AL26: {=MAX(_xlfn._xlws.FILTER($B26:$AF26, $B$2:$AF$2=AL$2))} -> 78.14079 | AM26: {=MAX(_xlfn._xlws.FILTER($B26:$AF26, $B$2:$AF$2=AM$2))} -> 77.049942 | AN26: {=MAX(_xlfn._xlws.FILTER($B26:$AF26, $B$2:$AF$2=AN$2))} -> 30.363622 | AO26: {=MAX(_xlfn._xlws.FILTER($B26:$AF26, $B$2:$AF$2=AO$2))} -> 0
A27: 12:00 PM | B27: 0 | C27: 132.36297 | D27: 96.475054 | E27: 84.175485 | F27: 81.12311 | G27: 78.370969 | H27: 35.807857 | I27: 0 | J27: 116.35052 | K27: 76.239311 | L27: 72.966765 | M27: 68.623386 | N27: 69.163807 | O27: 26.950967 | P27: 0 | Q27: 111.54678 | R27: 73.887481 | S27: 73.93752 | T27: 66.701891 | U27: 70.614935 | V27: 26.950967 | W27: 0 | X27: 115.28969 | Y27: 76.239311 | Z27: 77.840557 | AA27: 71.025255 | AB27: 75.458704 | AC27: 29.753147 | AD27: 0 | AE27: 119.55301 | AF27: 82.834442 | AI27: {=MAX(_xlfn._xlws.FILTER($D27:$AF27, $D$2:$AF$2=AI$2))} -> 119.55301 | AJ27: {=MAX(_xlfn._xlws.FILTER($B27:$AF27, $B$2:$AF$2=AJ$2))} -> 96.475054 | AK27: {=MAX(_xlfn._xlws.FILTER($B27:$AF27, $B$2:$AF$2=AK$2))} -> 84.175485 | AL27: {=MAX(_xlfn._xlws.FILTER($B27:$AF27, $B$2:$AF$2=AL$2))} -> 81.12311 | AM27: {=MAX(_xlfn._xlws.FILTER($B27:$AF27, $B$2:$AF$2=AM$2))} -> 78.370969 | AN27: {=MAX(_xlfn._xlws.FILTER($B27:$AF27, $B$2:$AF$2=AN$2))} -> 35.807857 | AO27: {=MAX(_xlfn._xlws.FILTER($B27:$AF27, $B$2:$AF$2=AO$2))} -> 0
A28: 12:30 PM | B28: 0 | C28: 145.48318 | D28: 107.21341 | E28: 92.281791 | F28: 89.879923 | G28: 86.076964 | H28: 40.45147 | I28: 0 | J28: 121.33439 | K28: 81.263219 | L28: 78.931405 | M28: 74.788182 | N28: 74.547995 | O28: 33.53609 | P28: 0 | Q28: 116.50063 | R28: 78.811312 | S28: 79.962207 | T28: 72.776617 | U28: 76.049163 | V28: 33.53609 | W28: 0 | X28: 120.79397 | Y28: 81.753601 | Z28: 84.075407 | AA28: 77.300136 | AB28: 81.063064 | AC28: 36.998784 | AD28: 0 | AE28: 125.09732 | AF28: 88.618942 | AI28: {=MAX(_xlfn._xlws.FILTER($D28:$AF28, $D$2:$AF$2=AI$2))} -> 125.09732 | AJ28: {=MAX(_xlfn._xlws.FILTER($B28:$AF28, $B$2:$AF$2=AJ$2))} -> 107.21341 | AK28: {=MAX(_xlfn._xlws.FILTER($B28:$AF28, $B$2:$AF$2=AK$2))} -> 92.281791 | AL28: {=MAX(_xlfn._xlws.FILTER($B28:$AF28, $B$2:$AF$2=AL$2))} -> 89.879923 | AM28: {=MAX(_xlfn._xlws.FILTER($B28:$AF28, $B$2:$AF$2=AM$2))} -> 86.076964 | AN28: {=MAX(_xlfn._xlws.FILTER($B28:$AF28, $B$2:$AF$2=AN$2))} -> 40.45147 | AO28: {=MAX(_xlfn._xlws.FILTER($B28:$AF28, $B$2:$AF$2=AO$2))} -> 0
A29: 1:00 PM | B29: 0 | C29: 142.05051 | D29: 107.41356 | E29: 94.23331 | F29: 94.203286 | G29: 89.229417 | H29: 42.84333 | I29: 0 | J29: 124.69701 | K29: 87.868358 | L29: 83.504963 | M29: 79.601927 | N29: 79.81209 | O29: 37.609258 | P29: 0 | Q29: 119.27279 | R29: 85.296357 | S29: 84.575796 | T29: 76.989895 | U29: 81.383313 | V29: 37.609258 | W29: 0 | X29: 124.15659 | Y29: 87.868358 | Z29: 88.869136 | AA29: 82.213959 | AB29: 86.607377 | AC29: 41.272108 | AD29: 0 | AE29: 128.49997 | AF29: 95.584361 | AI29: {=MAX(_xlfn._xlws.FILTER($D29:$AF29, $D$2:$AF$2=AI$2))} -> 128.49997 | AJ29: {=MAX(_xlfn._xlws.FILTER($B29:$AF29, $B$2:$AF$2=AJ$2))} -> 107.41356 | AK29: {=MAX(_xlfn._xlws.FILTER($B29:$AF29, $B$2:$AF$2=AK$2))} -> 94.23331 | AL29: {=MAX(_xlfn._xlws.FILTER($B29:$AF29, $B$2:$AF$2=AL$2))} -> 94.203286 | AM29: {=MAX(_xlfn._xlws.FILTER($B29:$AF29, $B$2:$AF$2=AM$2))} -> 89.229417 | AN29: {=MAX(_xlfn._xlws.FILTER($B29:$AF29, $B$2:$AF$2=AN$2))} -> 42.84333 | AO29: {=MAX(_xlfn._xlws.FILTER($B29:$AF29, $B$2:$AF$2=AO$2))} -> 0
A30: 1:30 PM | B30: 0 | C30: 145.253 | D30: 108.95476 | E30: 94.803753 | F30: 90.220188 | G30: 88.318708 | H30: 42.533089 | I30: 0 | J30: 127.15892 | K30: 92.622056 | L30: 86.217073 | M30: 83.915283 | N30: 83.014582 | O30: 37.73936 | P30: 0 | Q30: 122.22509 | R30: 89.459596 | S30: 87.287906 | T30: 81.283235 | U30: 84.60582 | V30: 37.198939 | W30: 0 | X30: 127.15892 | Y30: 92.622056 | Z30: 91.581246 | AA30: 86.537322 | AB30: 90.430351 | AC30: 41.472264 | AD30: 0 | AE30: 131.55234 | AF30: 100.52821 | AI30: {=MAX(_xlfn._xlws.FILTER($D30:$AF30, $D$2:$AF$2=AI$2))} -> 131.55234 | AJ30: {=MAX(_xlfn._xlws.FILTER($B30:$AF30, $B$2:$AF$2=AJ$2))} -> 108.95476 | AK30: {=MAX(_xlfn._xlws.FILTER($B30:$AF30, $B$2:$AF$2=AK$2))} -> 94.803753 | AL30: {=MAX(_xlfn._xlws.FILTER($B30:$AF30, $B$2:$AF$2=AL$2))} -> 90.220188 | AM30: {=MAX(_xlfn._xlws.FILTER($B30:$AF30, $B$2:$AF$2=AM$2))} -> 90.430351 | AN30: {=MAX(_xlfn._xlws.FILTER($B30:$AF30, $B$2:$AF$2=AN$2))} -> 42.533089 | AO30: {=MAX(_xlfn._xlws.FILTER($B30:$AF30, $B$2:$AF$2=AO$2))} -> 0
... A50: 11:30 PM | B50: 0 | C50: 0 | D50: 0 | E50: 0 | F50: 0 | G50: 0 | H50: 0 | I50: 0 | J50: 0 | K50: 0 | L50: 0 | M50: 0 | N50: 0 | O50: 0 | P50: 0 | Q50: 0 | R50: 0 | S50: 0 | T50: 0 | U50: 0 | V50: 0 | W50: 0 | X50: 0 | Y50: 0 | Z50: 0 | AA50: 0 | AB50: 0 | AC50: 0 | AD50: 0 | AE50: 0 | AF50: 0 | AI50: {=MAX(_xlfn._xlws.FILTER($D50:$AF50, $D$2:$AF$2=AI$2))} -> 0 | AJ50: {=MAX(_xlfn._xlws.FILTER($B50:$AF50, $B$2:$AF$2=AJ$2))} -> 0 | AK50: {=MAX(_xlfn._xlws.FILTER($B50:$AF50, $B$2:$AF$2=AK$2))} -> 0 | AL50: {=MAX(_xlfn._xlws.FILTER($B50:$AF50, $B$2:$AF$2=AL$2))} -> 0 | AM50: {=MAX(_xlfn._xlws.FILTER($B50:$AF50, $B$2:$AF$2=AM$2))} -> 0 | AN50: {=MAX(_xlfn._xlws.FILTER($B50:$AF50, $B$2:$AF$2=AN$2))} -> 0 | AO50: {=MAX(_xlfn._xlws.FILTER($B50:$AF50, $B$2:$AF$2=AO$2))} -> 0
B51: =MAX(B3:B50) -> 0 | C51: =MAX(C3:C50) -> 146.16371 | D51: =MAX(D3:D50) -> 108.95476 | E51: =MAX(E3:E50) -> 96.62517 | F51: =MAX(F3:F50) -> 94.203286 | G51: =MAX(G3:G50) -> 94.293356 | H51: =MAX(H3:H50) -> 42.84333 | I51: =MAX(I3:I50) -> 0 | ... AF51: =MAX(AF3:AF50) -> 101.78919

Sheet V-Vol Mar
A1: LOCK | B1: ='V-FTE Mar'!B1 -> 46082 | C1: ='V-FTE Mar'!C1 -> 46083 | D1: ='V-FTE Mar'!D1 -> 46084 | E1: ='V-FTE Mar'!E1 -> 46085 | F1: ='V-FTE Mar'!F1 -> 46086 | G1: ='V-FTE Mar'!G1 -> 46087 | H1: ='V-FTE Mar'!H1 -> 46088 | I1: ='V-FTE Mar'!I1 -> 46089 | ... AF1: ='V-FTE Mar'!AF1 -> 46112
A2: ='V-FTE Mar'!A2 -> 0 | B2: =TEXT(B1,"ddd") -> Sun | C2: =TEXT(C1,"ddd") -> Mon | D2: =TEXT(D1,"ddd") -> Tue | E2: =TEXT(E1,"ddd") -> Wed | F2: =TEXT(F1,"ddd") -> Thu | G2: =TEXT(G1,"ddd") -> Fri | H2: =TEXT(H1,"ddd") -> Sat | I2: =TEXT(I1,"ddd") -> Sun | ... AF2: =TEXT(AF1,"ddd") -> Tue
A3: 0 | B3: 0 | C3: 0 | D3: 0 | E3: 0 | F3: 0 | G3: 0 | H3: 0 | I3: 0 | J3: 0 | K3: 0 | L3: 0 | M3: 0 | N3: 0 | O3: 0 | P3: 0 | Q3: 0 | R3: 0 | S3: 0 | T3: 0 | U3: 0 | V3: 0 | W3: 0 | X3: 0 | Y3: 0 | Z3: 0 | AA3: 0 | AB3: 0 | AC3: 0 | AD3: 0 | AE3: 0 | AF3: 0
A4: 0.020833333 | B4: 0 | C4: 0 | D4: 0 | E4: 0 | F4: 0 | G4: 0 | H4: 0 | I4: 0 | J4: 0 | K4: 0 | L4: 0 | M4: 0 | N4: 0 | O4: 0 | P4: 0 | Q4: 0 | R4: 0 | S4: 0 | T4: 0 | U4: 0 | V4: 0 | W4: 0 | X4: 0 | Y4: 0 | Z4: 0 | AA4: 0 | AB4: 0 | AC4: 0 | AD4: 0 | AE4: 0 | AF4: 0
A5: 0.041666667 | B5: 0 | C5: 0 | D5: 0 | E5: 0 | F5: 0 | G5: 0 | H5: 0 | I5: 0 | J5: 0 | K5: 0 | L5: 0 | M5: 0 | N5: 0 | O5: 0 | P5: 0 | Q5: 0 | R5: 0 | S5: 0 | T5: 0 | U5: 0 | V5: 0 | W5: 0 | X5: 0 | Y5: 0 | Z5: 0 | AA5: 0 | AB5: 0 | AC5: 0 | AD5: 0 | AE5: 0 | AF5: 0
A6: 0.0625 | B6: 0 | C6: 0 | D6: 0 | E6: 0 | F6: 0 | G6: 0 | H6: 0 | I6: 0 | J6: 0 | K6: 0 | L6: 0 | M6: 0 | N6: 0 | O6: 0 | P6: 0 | Q6: 0 | R6: 0 | S6: 0 | T6: 0 | U6: 0 | V6: 0 | W6: 0 | X6: 0 | Y6: 0 | Z6: 0 | AA6: 0 | AB6: 0 | AC6: 0 | AD6: 0 | AE6: 0 | AF6: 0
A7: 0.083333333 | B7: 0 | C7: 0 | D7: 0 | E7: 0 | F7: 0 | G7: 0 | H7: 0 | I7: 0 | J7: 0 | K7: 0 | L7: 0 | M7: 0 | N7: 0 | O7: 0 | P7: 0 | Q7: 0 | R7: 0 | S7: 0 | T7: 0 | U7: 0 | V7: 0 | W7: 0 | X7: 0 | Y7: 0 | Z7: 0 | AA7: 0 | AB7: 0 | AC7: 0 | AD7: 0 | AE7: 0 | AF7: 0
A8: 0.10416667 | B8: 0 | C8: 0 | D8: 0 | E8: 0 | F8: 0 | G8: 0 | H8: 0 | I8: 0 | J8: 0 | K8: 0 | L8: 0 | M8: 0 | N8: 0 | O8: 0 | P8: 0 | Q8: 0 | R8: 0 | S8: 0 | T8: 0 | U8: 0 | V8: 0 | W8: 0 | X8: 0 | Y8: 0 | Z8: 0 | AA8: 0 | AB8: 0 | AC8: 0 | AD8: 0 | AE8: 0 | AF8: 0
A9: 0.125 | B9: 0 | C9: 0 | D9: 0 | E9: 0 | F9: 0 | G9: 0 | H9: 0 | I9: 0 | J9: 0 | K9: 0 | L9: 0 | M9: 0 | N9: 0 | O9: 0 | P9: 0 | Q9: 0 | R9: 0 | S9: 0 | T9: 0 | U9: 0 | V9: 0 | W9: 0 | X9: 0 | Y9: 0 | Z9: 0 | AA9: 0 | AB9: 0 | AC9: 0 | AD9: 0 | AE9: 0 | AF9: 0
A10: 0.14583333 | B10: 0 | C10: 0 | D10: 0 | E10: 0 | F10: 0 | G10: 0 | H10: 0 | I10: 0 | J10: 0 | K10: 0 | L10: 0 | M10: 0 | N10: 0 | O10: 0 | P10: 0 | Q10: 0 | R10: 0 | S10: 0 | T10: 0 | U10: 0 | V10: 0 | W10: 0 | X10: 0 | Y10: 0 | Z10: 0 | AA10: 0 | AB10: 0 | AC10: 0 | AD10: 0 | AE10: 0 | AF10: 0
A11: 0.16666667 | B11: 0 | C11: 0 | D11: 0 | E11: 0 | F11: 0 | G11: 0 | H11: 0 | I11: 0 | J11: 0 | K11: 0 | L11: 0 | M11: 0 | N11: 0 | O11: 0 | P11: 0 | Q11: 0 | R11: 0 | S11: 0 | T11: 0 | U11: 0 | V11: 0 | W11: 0 | X11: 0 | Y11: 0 | Z11: 0 | AA11: 0 | AB11: 0 | AC11: 0 | AD11: 0 | AE11: 0 | AF11: 0
A12: 0.1875 | B12: 0 | C12: 0 | D12: 0 | E12: 0 | F12: 0 | G12: 0 | H12: 0 | I12: 0 | J12: 0 | K12: 0 | L12: 0 | M12: 0 | N12: 0 | O12: 0 | P12: 0 | Q12: 0 | R12: 0 | S12: 0 | T12: 0 | U12: 0 | V12: 0 | W12: 0 | X12: 0 | Y12: 0 | Z12: 0 | AA12: 0 | AB12: 0 | AC12: 0 | AD12: 0 | AE12: 0 | AF12: 0
A13: 0.20833333 | B13: 0 | C13: 0 | D13: 0 | E13: 0 | F13: 0 | G13: 0 | H13: 0 | I13: 0 | J13: 0 | K13: 0 | L13: 0 | M13: 0 | N13: 0 | O13: 0 | P13: 0 | Q13: 0 | R13: 0 | S13: 0 | T13: 0 | U13: 0 | V13: 0 | W13: 0 | X13: 0 | Y13: 0 | Z13: 0 | AA13: 0 | AB13: 0 | AC13: 0 | AD13: 0 | AE13: 0 | AF13: 0
A14: 0.22916667 | B14: 0 | C14: 0 | D14: 0 | E14: 0 | F14: 0 | G14: 0 | H14: 0 | I14: 0 | J14: 0 | K14: 0 | L14: 0 | M14: 0 | N14: 0 | O14: 0 | P14: 0 | Q14: 0 | R14: 0 | S14: 0 | T14: 0 | U14: 0 | V14: 0 | W14: 0 | X14: 0 | Y14: 0 | Z14: 0 | AA14: 0 | AB14: 0 | AC14: 0 | AD14: 0 | AE14: 0 | AF14: 0
... A50: 0.97916667 | B50: 0 | C50: 0 | D50: 0 | E50: 0 | F50: 0 | G50: 0 | H50: 0 | I50: 0 | J50: 0 | K50: 0 | L50: 0 | M50: 0 | N50: 0 | O50: 0 | P50: 0 | Q50: 0 | R50: 0 | S50: 0 | T50: 0 | U50: 0 | V50: 0 | W50: 0 | X50: 0 | Y50: 0 | Z50: 0 | AA50: 0 | AB50: 0 | AC50: 0 | AD50: 0 | AE50: 0 | AF50: 0
A51: Volume | B51: =SUM(B3:B50) -> 0 | C51: =SUM(C3:C50) -> 4871 | D51: =SUM(D3:D50) -> 3847 | E51: =SUM(E3:E50) -> 3320 | F51: =SUM(F3:F50) -> 3245 | G51: =SUM(G3:G50) -> 3185 | H51: =SUM(H3:H50) -> 1271 | I51: =SUM(I3:I50) -> 0 | ... AF51: =SUM(AF3:AF50) -> 3625 | AG51: =SUM(B51:AF51) -> 80573

Sheet V-Hrs Mar
A1: LOCK | B1: ='V-FTE Mar'!B1 -> 46082 | C1: ='V-FTE Mar'!C1 -> 46083 | D1: ='V-FTE Mar'!D1 -> 46084 | E1: ='V-FTE Mar'!E1 -> 46085 | F1: ='V-FTE Mar'!F1 -> 46086 | G1: ='V-FTE Mar'!G1 -> 46087 | H1: ='V-FTE Mar'!H1 -> 46088 | I1: ='V-FTE Mar'!I1 -> 46089 | ... AF1: ='V-FTE Mar'!AF1 -> 46112
A2: ='V-FTE Mar'!A2 -> 0 | B2: =TEXT(B1,"ddd") -> Sun | C2: =TEXT(C1,"ddd") -> Mon | D2: =TEXT(D1,"ddd") -> Tue | E2: =TEXT(E1,"ddd") -> Wed | F2: =TEXT(F1,"ddd") -> Thu | G2: =TEXT(G1,"ddd") -> Fri | H2: =TEXT(H1,"ddd") -> Sat | I2: =TEXT(I1,"ddd") -> Sun | ... AF2: =TEXT(AF1,"ddd") -> Tue
A3: 12:00 AM | B3: ='V-FTE Mar'!B3/2 -> 0 | C3: ='V-FTE Mar'!C3/2 -> 0 | D3: ='V-FTE Mar'!D3/2 -> 0 | E3: ='V-FTE Mar'!E3/2 -> 0 | F3: ='V-FTE Mar'!F3/2 -> 0 | G3: ='V-FTE Mar'!G3/2 -> 0 | H3: ='V-FTE Mar'!H3/2 -> 0 | I3: ='V-FTE Mar'!I3/2 -> 0 | ... AE3: ='V-FTE Mar'!AE3/2 -> 0
A4: 12:30 AM | B4: ='V-FTE Mar'!B4/2 -> 0 | C4: ='V-FTE Mar'!C4/2 -> 0 | D4: ='V-FTE Mar'!D4/2 -> 0 | E4: ='V-FTE Mar'!E4/2 -> 0 | F4: ='V-FTE Mar'!F4/2 -> 0 | G4: ='V-FTE Mar'!G4/2 -> 0 | H4: ='V-FTE Mar'!H4/2 -> 0 | I4: ='V-FTE Mar'!I4/2 -> 0 | ... AE4: ='V-FTE Mar'!AE4/2 -> 0
A5: 1:00 AM | B5: ='V-FTE Mar'!B5/2 -> 0 | C5: ='V-FTE Mar'!C5/2 -> 0 | D5: ='V-FTE Mar'!D5/2 -> 0 | E5: ='V-FTE Mar'!E5/2 -> 0 | F5: ='V-FTE Mar'!F5/2 -> 0 | G5: ='V-FTE Mar'!G5/2 -> 0 | H5: ='V-FTE Mar'!H5/2 -> 0 | I5: ='V-FTE Mar'!I5/2 -> 0 | ... AE5: ='V-FTE Mar'!AE5/2 -> 0
A6: 1:30 AM | B6: ='V-FTE Mar'!B6/2 -> 0 | C6: ='V-FTE Mar'!C6/2 -> 0 | D6: ='V-FTE Mar'!D6/2 -> 0 | E6: ='V-FTE Mar'!E6/2 -> 0 | F6: ='V-FTE Mar'!F6/2 -> 0 | G6: ='V-FTE Mar'!G6/2 -> 0 | H6: ='V-FTE Mar'!H6/2 -> 0 | I6: ='V-FTE Mar'!I6/2 -> 0 | ... AE6: ='V-FTE Mar'!AE6/2 -> 0
A7: 2:00 AM | B7: ='V-FTE Mar'!B7/2 -> 0 | C7: ='V-FTE Mar'!C7/2 -> 0 | D7: ='V-FTE Mar'!D7/2 -> 0 | E7: ='V-FTE Mar'!E7/2 -> 0 | F7: ='V-FTE Mar'!F7/2 -> 0 | G7: ='V-FTE Mar'!G7/2 -> 0 | H7: ='V-FTE Mar'!H7/2 -> 0 | I7: ='V-FTE Mar'!I7/2 -> 0 | ... AE7: ='V-FTE Mar'!AE7/2 -> 0
A8: 2:30 AM | B8: ='V-FTE Mar'!B8/2 -> 0 | C8: ='V-FTE Mar'!C8/2 -> 0 | D8: ='V-FTE Mar'!D8/2 -> 0 | E8: ='V-FTE Mar'!E8/2 -> 0 | F8: ='V-FTE Mar'!F8/2 -> 0 | G8: ='V-FTE Mar'!G8/2 -> 0 | H8: ='V-FTE Mar'!H8/2 -> 0 | I8: ='V-FTE Mar'!I8/2 -> 0 | ... AE8: ='V-FTE Mar'!AE8/2 -> 0
A9: 3:00 AM | B9: ='V-FTE Mar'!B9/2 -> 0 | C9: ='V-FTE Mar'!C9/2 -> 0 | D9: ='V-FTE Mar'!D9/2 -> 0 | E9: ='V-FTE Mar'!E9/2 -> 0 | F9: ='V-FTE Mar'!F9/2 -> 0 | G9: ='V-FTE Mar'!G9/2 -> 0 | H9: ='V-FTE Mar'!H9/2 -> 0 | I9: ='V-FTE Mar'!I9/2 -> 0 | ... AE9: ='V-FTE Mar'!AE9/2 -> 0
A10: 3:30 AM | B10: ='V-FTE Mar'!B10/2 -> 0 | C10: ='V-FTE Mar'!C10/2 -> 0 | D10: ='V-FTE Mar'!D10/2 -> 0 | E10: ='V-FTE Mar'!E10/2 -> 0 | F10: ='V-FTE Mar'!F10/2 -> 0 | G10: ='V-FTE Mar'!G10/2 -> 0 | H10: ='V-FTE Mar'!H10/2 -> 0 | I10: ='V-FTE Mar'!I10/2 -> 0 | ... AE10: ='V-FTE Mar'!AE10/2 -> 0
A11: 4:00 AM | B11: ='V-FTE Mar'!B11/2 -> 0 | C11: ='V-FTE Mar'!C11/2 -> 0 | D11: ='V-FTE Mar'!D11/2 -> 0 | E11: ='V-FTE Mar'!E11/2 -> 0 | F11: ='V-FTE Mar'!F11/2 -> 0 | G11: ='V-FTE Mar'!G11/2 -> 0 | H11: ='V-FTE Mar'!H11/2 -> 0 | I11: ='V-FTE Mar'!I11/2 -> 0 | ... AE11: ='V-FTE Mar'!AE11/2 -> 0
A12: 4:30 AM | B12: ='V-FTE Mar'!B12/2 -> 0 | C12: ='V-FTE Mar'!C12/2 -> 0 | D12: ='V-FTE Mar'!D12/2 -> 0 | E12: ='V-FTE Mar'!E12/2 -> 0 | F12: ='V-FTE Mar'!F12/2 -> 0 | G12: ='V-FTE Mar'!G12/2 -> 0 | H12: ='V-FTE Mar'!H12/2 -> 0 | I12: ='V-FTE Mar'!I12/2 -> 0 | ... AE12: ='V-FTE Mar'!AE12/2 -> 0
A13: 5:00 AM | B13: ='V-FTE Mar'!B13/2 -> 0 | C13: ='V-FTE Mar'!C13/2 -> 0 | D13: ='V-FTE Mar'!D13/2 -> 0 | E13: ='V-FTE Mar'!E13/2 -> 0 | F13: ='V-FTE Mar'!F13/2 -> 0 | G13: ='V-FTE Mar'!G13/2 -> 0 | H13: ='V-FTE Mar'!H13/2 -> 0 | I13: ='V-FTE Mar'!I13/2 -> 0 | ... AE13: ='V-FTE Mar'!AE13/2 -> 0
A14: 5:30 AM | B14: ='V-FTE Mar'!B14/2 -> 0 | C14: ='V-FTE Mar'!C14/2 -> 0 | D14: ='V-FTE Mar'!D14/2 -> 0 | E14: ='V-FTE Mar'!E14/2 -> 0 | F14: ='V-FTE Mar'!F14/2 -> 0 | G14: ='V-FTE Mar'!G14/2 -> 0 | H14: ='V-FTE Mar'!H14/2 -> 0 | I14: ='V-FTE Mar'!I14/2 -> 0 | ... AE14: ='V-FTE Mar'!AE14/2 -> 0
... A18: 7:30 AM | B18: ='V-FTE Mar'!B18/2 -> 0 | C18: ='V-FTE Mar'!C18/2 -> 0 | D18: ='V-FTE Mar'!D18/2 -> 0 | E18: ='V-FTE Mar'!E18/2 -> 0 | F18: ='V-FTE Mar'!F18/2 -> 0 | G18: ='V-FTE Mar'!G18/2 -> 0 | H18: ='V-FTE Mar'!H18/2 -> 0 | I18: ='V-FTE Mar'!I18/2 -> 0 | ... AE18: ='V-FTE Mar'!AE18/2 -> 0
A19: 8:00 AM | B19: ='V-FTE Mar'!B19/2 -> 0 | C19: ='V-FTE Mar'!C19/2 -> 4.3133556 | D19: ='V-FTE Mar'!D19/2 -> 2.8572228 | E19: ='V-FTE Mar'!E19/2 -> 2.1917051 | F19: ='V-FTE Mar'!F19/2 -> 2.5019464 | G19: ='V-FTE Mar'!G19/2 -> 2.6370515 | H19: ='V-FTE Mar'!H19/2 -> 0 | I19: ='V-FTE Mar'!I19/2 -> 0 | ... AF19: ='V-FTE Mar'!AF19/2 -> 2.3868569
A20: 8:30 AM | B20: ='V-FTE Mar'!B20/2 -> 0 | C20: ='V-FTE Mar'!C20/2 -> 8.2364076 | D20: ='V-FTE Mar'!D20/2 -> 5.1690213 | E20: ='V-FTE Mar'!E20/2 -> 4.343379 | F20: ='V-FTE Mar'!F20/2 -> 4.5085074 | G20: ='V-FTE Mar'!G20/2 -> 4.6986554 | H20: ='V-FTE Mar'!H20/2 -> 0 | I20: ='V-FTE Mar'!I20/2 -> 0 | ... AF20: ='V-FTE Mar'!AF20/2 -> 4.3233634
A21: 9:00 AM | B21: ='V-FTE Mar'!B21/2 -> 0 | C21: ='V-FTE Mar'!C21/2 -> 17.433563 | D21: ='V-FTE Mar'!D21/2 -> 11.223732 | E21: ='V-FTE Mar'!E21/2 -> 9.0720577 | F21: ='V-FTE Mar'!F21/2 -> 9.432338 | G21: ='V-FTE Mar'!G21/2 -> 9.522408 | H21: ='V-FTE Mar'!H21/2 -> 2.8872462 | I21: ='V-FTE Mar'!I21/2 -> 0 | ... AF21: ='V-FTE Mar'!AF21/2 -> 8.5116217
A22: 9:30 AM | B22: ='V-FTE Mar'!B22/2 -> 0 | C22: ='V-FTE Mar'!C22/2 -> 23.898592 | D22: ='V-FTE Mar'!D22/2 -> 17.333485 | E22: ='V-FTE Mar'!E22/2 -> 15.637165 | F22: ='V-FTE Mar'!F22/2 -> 14.966643 | G22: ='V-FTE Mar'!G22/2 -> 14.206052 | H22: ='V-FTE Mar'!H22/2 -> 4.668632 | I22: ='V-FTE Mar'!I22/2 -> 0 | ... AF22: ='V-FTE Mar'!AF22/2 -> 13.365398
A23: 10:00 AM | B23: ='V-FTE Mar'!B23/2 -> 0 | C23: ='V-FTE Mar'!C23/2 -> 35.59269 | D23: ='V-FTE Mar'!D23/2 -> 24.934398 | E23: ='V-FTE Mar'!E23/2 -> 21.731907 | F23: ='V-FTE Mar'!F23/2 -> 22.177253 | G23: ='V-FTE Mar'!G23/2 -> 20.646062 | H23: ='V-FTE Mar'!H23/2 -> 7.4357847 | I23: ='V-FTE Mar'!I23/2 -> 0 | ... AF23: ='V-FTE Mar'!AF23/2 -> 17.843882
A24: 10:30 AM | B24: ='V-FTE Mar'!B24/2 -> 0 | C24: ='V-FTE Mar'!C24/2 -> 40.596582 | D24: ='V-FTE Mar'!D24/2 -> 30.353614 | E24: ='V-FTE Mar'!E24/2 -> 25.945184 | F24: ='V-FTE Mar'!F24/2 -> 26.44057 | G24: ='V-FTE Mar'!G24/2 -> 24.774273 | H24: ='V-FTE Mar'!H24/2 -> 10.162906 | I24: ='V-FTE Mar'!I24/2 -> 0 | ... AF24: ='V-FTE Mar'!AF24/2 -> 23.233074
A25: 11:00 AM | B25: ='V-FTE Mar'!B25/2 -> 0 | C25: ='V-FTE Mar'!C25/2 -> 49.048157 | D25: ='V-FTE Mar'!D25/2 -> 37.464146 | E25: ='V-FTE Mar'!E25/2 -> 33.360953 | F25: ='V-FTE Mar'!F25/2 -> 33.250868 | G25: ='V-FTE Mar'!G25/2 -> 30.358618 | H25: ='V-FTE Mar'!H25/2 -> 13.070168 | I25: ='V-FTE Mar'!I25/2 -> 0 | ... AF25: ='V-FTE Mar'!AF25/2 -> 30.228517
A26: 11:30 AM | B26: ='V-FTE Mar'!B26/2 -> 0 | C26: ='V-FTE Mar'!C26/2 -> 63.659524 | D26: ='V-FTE Mar'!D26/2 -> 43.358731 | E26: ='V-FTE Mar'!E26/2 -> 38.890255 | F26: ='V-FTE Mar'!F26/2 -> 39.070395 | G26: ='V-FTE Mar'!G26/2 -> 38.524971 | H26: ='V-FTE Mar'!H26/2 -> 15.181811 | I26: ='V-FTE Mar'!I26/2 -> 0 | ... AF26: ='V-FTE Mar'!AF26/2 -> 37.519188
A27: 12:00 PM | B27: ='V-FTE Mar'!B27/2 -> 0 | C27: ='V-FTE Mar'!C27/2 -> 66.181486 | D27: ='V-FTE Mar'!D27/2 -> 48.237527 | E27: ='V-FTE Mar'!E27/2 -> 42.087743 | F27: ='V-FTE Mar'!F27/2 -> 40.561555 | G27: ='V-FTE Mar'!G27/2 -> 39.185485 | H27: ='V-FTE Mar'!H27/2 -> 17.903929 | I27: ='V-FTE Mar'!I27/2 -> 0 | ... AF27: ='V-FTE Mar'!AF27/2 -> 41.417221
A28: 12:30 PM | B28: ='V-FTE Mar'!B28/2 -> 0 | C28: ='V-FTE Mar'!C28/2 -> 72.74159 | D28: ='V-FTE Mar'!D28/2 -> 53.606704 | E28: ='V-FTE Mar'!E28/2 -> 46.140896 | F28: ='V-FTE Mar'!F28/2 -> 44.939961 | G28: ='V-FTE Mar'!G28/2 -> 43.038482 | H28: ='V-FTE Mar'!H28/2 -> 20.225735 | I28: ='V-FTE Mar'!I28/2 -> 0 | ... AF28: ='V-FTE Mar'!AF28/2 -> 44.309471
A29: 1:00 PM | B29: ='V-FTE Mar'!B29/2 -> 0 | C29: ='V-FTE Mar'!C29/2 -> 71.025255 | D29: ='V-FTE Mar'!D29/2 -> 53.706782 | E29: ='V-FTE Mar'!E29/2 -> 47.116655 | F29: ='V-FTE Mar'!F29/2 -> 47.101643 | G29: ='V-FTE Mar'!G29/2 -> 44.614708 | H29: ='V-FTE Mar'!H29/2 -> 21.421665 | I29: ='V-FTE Mar'!I29/2 -> 0 | ... AF29: ='V-FTE Mar'!AF29/2 -> 47.79218
A30: 1:30 PM | B30: ='V-FTE Mar'!B30/2 -> 0 | C30: ='V-FTE Mar'!C30/2 -> 72.6265 | D30: ='V-FTE Mar'!D30/2 -> 54.477381 | E30: ='V-FTE Mar'!E30/2 -> 47.401877 | F30: ='V-FTE Mar'!F30/2 -> 45.110094 | G30: ='V-FTE Mar'!G30/2 -> 44.159354 | H30: ='V-FTE Mar'!H30/2 -> 21.266544 | I30: ='V-FTE Mar'!I30/2 -> 0 | ... AF30: ='V-FTE Mar'!AF30/2 -> 50.264103
... A50: 11:30 PM | B50: ='V-FTE Mar'!B50/2 -> 0 | C50: ='V-FTE Mar'!C50/2 -> 0 | D50: ='V-FTE Mar'!D50/2 -> 0 | E50: ='V-FTE Mar'!E50/2 -> 0 | F50: ='V-FTE Mar'!F50/2 -> 0 | G50: ='V-FTE Mar'!G50/2 -> 0 | H50: ='V-FTE Mar'!H50/2 -> 0 | I50: ='V-FTE Mar'!I50/2 -> 0 | ... AF50: ='V-FTE Mar'!AF50/2 -> 0
A51: Hours | B51: =SUM(B3:B50) -> 0 | C51: =SUM(C3:C50) -> 1323.2294 | D51: =SUM(D3:D50) -> 990.51058 | E51: =SUM(E3:E50) -> 890.22256 | F51: =SUM(F3:F50) -> 853.98937 | G51: =SUM(G3:G50) -> 847.6044 | H51: =SUM(H3:H50) -> 335.43095 | I51: =SUM(I3:I50) -> 0 | ... AF51: =SUM(AF3:AF50) -> 945.28539 | AG51: =SUM(B51:AF51) -> 21550

Sheet V-FTE Apr
A1: Time Period | B1: 46113 | C1: =B1+1 -> 46114 | D1: =C1+1 -> 46115 | E1: =D1+1 -> 46116 | F1: =E1+1 -> 46117 | G1: =F1+1 -> 46118 | H1: =G1+1 -> 46119 | I1: =H1+1 -> 46120 | J1: =I1+1 -> 46121 | ... AF1: =AE1+1 -> 46143 | AI1: MAX REQUIRED FTE
B2: =TEXT(B1,"ddd") -> Wed | C2: =TEXT(C1,"ddd") -> Thu | D2: =TEXT(D1,"ddd") -> Fri | E2: =TEXT(E1,"ddd") -> Sat | F2: =TEXT(F1,"ddd") -> Sun | G2: =TEXT(G1,"ddd") -> Mon | H2: =TEXT(H1,"ddd") -> Tue | I2: =TEXT(I1,"ddd") -> Wed | ... AF2: =TEXT(AF1,"ddd") -> Fri | AI2: Mon | AJ2: Tue | AK2: Wed | AL2: Thu | AM2: Fri | AN2: Sat | AO2: Sun
A3: 12:00 AM | B3: 0 | C3: 0 | D3: 0 | E3: 0 | F3: 0 | G3: 0 | H3: 0 | I3: 0 | J3: 0 | K3: 0 | L3: 0 | M3: 0 | N3: 0 | O3: 0 | P3: 0 | Q3: 0 | R3: 0 | S3: 0 | T3: 0 | U3: 0 | V3: 0 | W3: 0 | X3: 0 | Y3: 0 | Z3: 0 | AA3: 0 | AB3: 0 | AC3: 0 | AD3: 0 | AE3: 0
A4: 12:30 AM | B4: 0 | C4: 0 | D4: 0 | E4: 0 | F4: 0 | G4: 0 | H4: 0 | I4: 0 | J4: 0 | K4: 0 | L4: 0 | M4: 0 | N4: 0 | O4: 0 | P4: 0 | Q4: 0 | R4: 0 | S4: 0 | T4: 0 | U4: 0 | V4: 0 | W4: 0 | X4: 0 | Y4: 0 | Z4: 0 | AA4: 0 | AB4: 0 | AC4: 0 | AD4: 0 | AE4: 0
A5: 1:00 AM | B5: 0 | C5: 0 | D5: 0 | E5: 0 | F5: 0 | G5: 0 | H5: 0 | I5: 0 | J5: 0 | K5: 0 | L5: 0 | M5: 0 | N5: 0 | O5: 0 | P5: 0 | Q5: 0 | R5: 0 | S5: 0 | T5: 0 | U5: 0 | V5: 0 | W5: 0 | X5: 0 | Y5: 0 | Z5: 0 | AA5: 0 | AB5: 0 | AC5: 0 | AD5: 0 | AE5: 0
A6: 1:30 AM | B6: 0 | C6: 0 | D6: 0 | E6: 0 | F6: 0 | G6: 0 | H6: 0 | I6: 0 | J6: 0 | K6: 0 | L6: 0 | M6: 0 | N6: 0 | O6: 0 | P6: 0 | Q6: 0 | R6: 0 | S6: 0 | T6: 0 | U6: 0 | V6: 0 | W6: 0 | X6: 0 | Y6: 0 | Z6: 0 | AA6: 0 | AB6: 0 | AC6: 0 | AD6: 0 | AE6: 0
A7: 2:00 AM | B7: 0 | C7: 0 | D7: 0 | E7: 0 | F7: 0 | G7: 0 | H7: 0 | I7: 0 | J7: 0 | K7: 0 | L7: 0 | M7: 0 | N7: 0 | O7: 0 | P7: 0 | Q7: 0 | R7: 0 | S7: 0 | T7: 0 | U7: 0 | V7: 0 | W7: 0 | X7: 0 | Y7: 0 | Z7: 0 | AA7: 0 | AB7: 0 | AC7: 0 | AD7: 0 | AE7: 0
A8: 2:30 AM | B8: 0 | C8: 0 | D8: 0 | E8: 0 | F8: 0 | G8: 0 | H8: 0 | I8: 0 | J8: 0 | K8: 0 | L8: 0 | M8: 0 | N8: 0 | O8: 0 | P8: 0 | Q8: 0 | R8: 0 | S8: 0 | T8: 0 | U8: 0 | V8: 0 | W8: 0 | X8: 0 | Y8: 0 | Z8: 0 | AA8: 0 | AB8: 0 | AC8: 0 | AD8: 0 | AE8: 0
A9: 3:00 AM | B9: 0 | C9: 0 | D9: 0 | E9: 0 | F9: 0 | G9: 0 | H9: 0 | I9: 0 | J9: 0 | K9: 0 | L9: 0 | M9: 0 | N9: 0 | O9: 0 | P9: 0 | Q9: 0 | R9: 0 | S9: 0 | T9: 0 | U9: 0 | V9: 0 | W9: 0 | X9: 0 | Y9: 0 | Z9: 0 | AA9: 0 | AB9: 0 | AC9: 0 | AD9: 0 | AE9: 0
A10: 3:30 AM | B10: 0 | C10: 0 | D10: 0 | E10: 0 | F10: 0 | G10: 0 | H10: 0 | I10: 0 | J10: 0 | K10: 0 | L10: 0 | M10: 0 | N10: 0 | O10: 0 | P10: 0 | Q10: 0 | R10: 0 | S10: 0 | T10: 0 | U10: 0 | V10: 0 | W10: 0 | X10: 0 | Y10: 0 | Z10: 0 | AA10: 0 | AB10: 0 | AC10: 0 | AD10: 0 | AE10: 0
A11: 4:00 AM | B11: 0 | C11: 0 | D11: 0 | E11: 0 | F11: 0 | G11: 0 | H11: 0 | I11: 0 | J11: 0 | K11: 0 | L11: 0 | M11: 0 | N11: 0 | O11: 0 | P11: 0 | Q11: 0 | R11: 0 | S11: 0 | T11: 0 | U11: 0 | V11: 0 | W11: 0 | X11: 0 | Y11: 0 | Z11: 0 | AA11: 0 | AB11: 0 | AC11: 0 | AD11: 0 | AE11: 0
A12: 4:30 AM | B12: 0 | C12: 0 | D12: 0 | E12: 0 | F12: 0 | G12: 0 | H12: 0 | I12: 0 | J12: 0 | K12: 0 | L12: 0 | M12: 0 | N12: 0 | O12: 0 | P12: 0 | Q12: 0 | R12: 0 | S12: 0 | T12: 0 | U12: 0 | V12: 0 | W12: 0 | X12: 0 | Y12: 0 | Z12: 0 | AA12: 0 | AB12: 0 | AC12: 0 | AD12: 0 | AE12: 0
A13: 5:00 AM | B13: 0 | C13: 0 | D13: 0 | E13: 0 | F13: 0 | G13: 0 | H13: 0 | I13: 0 | J13: 0 | K13: 0 | L13: 0 | M13: 0 | N13: 0 | O13: 0 | P13: 0 | Q13: 0 | R13: 0 | S13: 0 | T13: 0 | U13: 0 | V13: 0 | W13: 0 | X13: 0 | Y13: 0 | Z13: 0 | AA13: 0 | AB13: 0 | AC13: 0 | AD13: 0 | AE13: 0
A14: 5:30 AM | B14: 0 | C14: 0 | D14: 0 | E14: 0 | F14: 0 | G14: 0 | H14: 0 | I14: 0 | J14: 0 | K14: 0 | L14: 0 | M14: 0 | N14: 0 | O14: 0 | P14: 0 | Q14: 0 | R14: 0 | S14: 0 | T14: 0 | U14: 0 | V14: 0 | W14: 0 | X14: 0 | Y14: 0 | Z14: 0 | AA14: 0 | AB14: 0 | AC14: 0 | AD14: 0 | AE14: 0
... A18: 7:30 AM | B18: 0 | C18: 0 | D18: 0 | E18: 0 | F18: 0 | G18: 0 | H18: 0 | I18: 0 | J18: 0 | K18: 0 | L18: 0 | M18: 0 | N18: 0 | O18: 0 | P18: 0 | Q18: 0 | R18: 0 | S18: 0 | T18: 0 | U18: 0 | V18: 0 | W18: 0 | X18: 0 | Y18: 0 | Z18: 0 | AA18: 0 | AB18: 0 | AC18: 0 | AD18: 0 | AE18: 0
A19: 8:00 AM | B19: 3.2351427 | C19: 3.4422707 | D19: 3.7085782 | E19: 0 | F19: 0 | G19: 5.2077906 | H19: 3.2745956 | I19: 2.9392455 | J19: 3.1167838 | K19: 3.4028177 | L19: 0 | M19: 0 | N19: 4.8823037 | O19: 2.9786984 | P19: 2.9392455 | Q19: 3.1167838 | R19: 3.0871941 | S19: 0 | T19: 0 | U19: 4.8823037 | V19: 2.9786984 | W19: 2.9392455 | X19: 3.1167838 | Y19: 3.4028177 | Z19: 0 | AA19: 0 | AB19: 5.2077906 | AC19: 2.9786984 | AD19: 2.9392455 | AE19: 2.8011601 | AI19: {=MAX(_xlfn._xlws.FILTER($D19:$AF19, $D$2:$AF$2=AI$2))} -> 5.2077906 | AJ19: {=MAX(_xlfn._xlws.FILTER($B19:$AF19, $B$2:$AF$2=AJ$2))} -> 3.2745956 | AK19: {=MAX(_xlfn._xlws.FILTER($B19:$AF19, $B$2:$AF$2=AK$2))} -> 3.2351427 | AL19: {=MAX(_xlfn._xlws.FILTER($B19:$AF19, $B$2:$AF$2=AL$2))} -> 3.4422707 | AM19: {=MAX(_xlfn._xlws.FILTER($B19:$AF19, $B$2:$AF$2=AM$2))} -> 3.7085782 | AN19: {=MAX(_xlfn._xlws.FILTER($B19:$AF19, $B$2:$AF$2=AN$2))} -> 0 | AO19: {=MAX(_xlfn._xlws.FILTER($B19:$AF19, $B$2:$AF$2=AO$2))} -> 0
A20: 8:30 AM | B20: 6.4604221 | C20: 6.3420632 | D20: 6.3519264 | E20: 0 | F20: 0 | G20: 9.2517189 | H20: 5.8489012 | I20: 6.1250719 | J20: 5.9869866 | K20: 6.006713 | L20: 0 | M20: 0 | N20: 8.5218392 | O20: 5.5234143 | P20: 6.1250719 | Q20: 5.9869866 | R20: 5.6516364 | S20: 0 | T20: 0 | U20: 8.8867791 | V20: 5.5234143 | W20: 6.1250719 | X20: 5.9869866 | Y20: 6.006713 | Z20: 0 | AA20: 0 | AB20: 8.8867791 | AC20: 5.5234143 | AD20: 5.4445084 | AE20: 5.2866965 | AI20: {=MAX(_xlfn._xlws.FILTER($D20:$AF20, $D$2:$AF$2=AI$2))} -> 9.2517189 | AJ20: {=MAX(_xlfn._xlws.FILTER($B20:$AF20, $B$2:$AF$2=AJ$2))} -> 5.8489012 | AK20: {=MAX(_xlfn._xlws.FILTER($B20:$AF20, $B$2:$AF$2=AK$2))} -> 6.4604221 | AL20: {=MAX(_xlfn._xlws.FILTER($B20:$AF20, $B$2:$AF$2=AL$2))} -> 6.3420632 | AM20: {=MAX(_xlfn._xlws.FILTER($B20:$AF20, $B$2:$AF$2=AM$2))} -> 6.3519264 | AN20: {=MAX(_xlfn._xlws.FILTER($B20:$AF20, $B$2:$AF$2=AN$2))} -> 0 | AO20: {=MAX(_xlfn._xlws.FILTER($B20:$AF20, $B$2:$AF$2=AO$2))} -> 0
A21: 9:00 AM | B21: 11.875341 | C21: 11.470948 | D21: 11.579444 | E21: 3.1661 | F21: 0 | G21: 16.698465 | H21: 10.800248 | I21: 10.780521 | J21: 10.741068 | K21: 10.474761 | L21: 3.1661 | M21: 0 | N21: 15.544466 | O21: 10.455034 | P21: 10.780521 | Q21: 10.376128 | R21: 10.474761 | S21: 2.8406131 | T21: 0 | U21: 15.929132 | V21: 10.109821 | W21: 10.780521 | X21: 10.376128 | Y21: 10.474761 | Z21: 2.8406131 | AA21: 0 | AB21: 16.313799 | AC21: 10.109821 | AD21: 10.050641 | AE21: 9.2714454 | AI21: {=MAX(_xlfn._xlws.FILTER($D21:$AF21, $D$2:$AF$2=AI$2))} -> 16.698465 | AJ21: {=MAX(_xlfn._xlws.FILTER($B21:$AF21, $B$2:$AF$2=AJ$2))} -> 10.800248 | AK21: {=MAX(_xlfn._xlws.FILTER($B21:$AF21, $B$2:$AF$2=AK$2))} -> 11.875341 | AL21: {=MAX(_xlfn._xlws.FILTER($B21:$AF21, $B$2:$AF$2=AL$2))} -> 11.470948 | AM21: {=MAX(_xlfn._xlws.FILTER($B21:$AF21, $B$2:$AF$2=AM$2))} -> 11.579444 | AN21: {=MAX(_xlfn._xlws.FILTER($B21:$AF21, $B$2:$AF$2=AN$2))} -> 3.1661 | AO21: {=MAX(_xlfn._xlws.FILTER($B21:$AF21, $B$2:$AF$2=AO$2))} -> 0
A22: 9:30 AM | B22: 18.799335 | C22: 17.063405 | D22: 17.428345 | E22: 4.9020302 | F22: 0 | G22: 25.417569 | H22: 16.737918 | I22: 16.787234 | J22: 15.899543 | K22: 15.909406 | L22: 4.5469535 | M22: 0 | N22: 24.20439 | O22: 16.363115 | P22: 16.787234 | Q22: 15.899543 | R22: 15.524739 | S22: 4.5469535 | T22: 0 | U22: 24.20439 | V22: 15.988312 | W22: 16.787234 | X22: 15.899543 | Y22: 15.909406 | Z22: 4.5469535 | AA22: 0 | AB22: 24.608783 | AC22: 15.988312 | AD22: 15.574056 | AE22: 13.936758 | AI22: {=MAX(_xlfn._xlws.FILTER($D22:$AF22, $D$2:$AF$2=AI$2))} -> 25.417569 | AJ22: {=MAX(_xlfn._xlws.FILTER($B22:$AF22, $B$2:$AF$2=AJ$2))} -> 16.737918 | AK22: {=MAX(_xlfn._xlws.FILTER($B22:$AF22, $B$2:$AF$2=AK$2))} -> 18.799335 | AL22: {=MAX(_xlfn._xlws.FILTER($B22:$AF22, $B$2:$AF$2=AL$2))} -> 17.063405 | AM22: {=MAX(_xlfn._xlws.FILTER($B22:$AF22, $B$2:$AF$2=AM$2))} -> 17.428345 | AN22: {=MAX(_xlfn._xlws.FILTER($B22:$AF22, $B$2:$AF$2=AN$2))} -> 4.9020302 | AO22: {=MAX(_xlfn._xlws.FILTER($B22:$AF22, $B$2:$AF$2=AO$2))} -> 0
A23: 10:00 AM | B23: 24.62851 | C23: 22.557229 | D23: 22.912306 | E23: 7.5552417 | F23: 0 | G23: 33.160212 | H23: 22.330375 | I23: 22.576956 | J23: 20.910068 | K23: 20.900205 | L23: 7.1804386 | M23: 0 | N23: 31.463735 | O23: 21.551179 | P23: 22.1627 | Q23: 20.505676 | R23: 20.091419 | S23: 7.1804386 | T23: 0 | U23: 31.463735 | V23: 21.156649 | W23: 22.1627 | X23: 20.910068 | Y23: 20.495812 | Z23: 7.1804386 | AA23: 0 | AB23: 32.311974 | AC23: 21.551179 | AD23: 20.929795 | AE23: 18.030002 | AI23: {=MAX(_xlfn._xlws.FILTER($D23:$AF23, $D$2:$AF$2=AI$2))} -> 33.160212 | AJ23: {=MAX(_xlfn._xlws.FILTER($B23:$AF23, $B$2:$AF$2=AJ$2))} -> 22.330375 | AK23: {=MAX(_xlfn._xlws.FILTER($B23:$AF23, $B$2:$AF$2=AK$2))} -> 24.62851 | AL23: {=MAX(_xlfn._xlws.FILTER($B23:$AF23, $B$2:$AF$2=AL$2))} -> 22.557229 | AM23: {=MAX(_xlfn._xlws.FILTER($B23:$AF23, $B$2:$AF$2=AM$2))} -> 22.912306 | AN23: {=MAX(_xlfn._xlws.FILTER($B23:$AF23, $B$2:$AF$2=AN$2))} -> 7.5552417 | AO23: {=MAX(_xlfn._xlws.FILTER($B23:$AF23, $B$2:$AF$2=AO$2))} -> 0
A24: 10:30 AM | B24: 30.694402 | C24: 27.607208 | D24: 28.702028 | E24: 10.56353 | F24: 0 | G24: 41.090257 | H24: 28.780934 | I24: 27.79461 | J24: 25.545791 | K24: 25.831825 | L24: 10.159137 | M24: 0 | N24: 38.930207 | O24: 27.972148 | P24: 27.380354 | Q24: 25.545791 | R24: 25.013176 | S24: 10.159137 | T24: 0 | U24: 38.930207 | V24: 27.567755 | W24: 27.79461 | X24: 25.545791 | Y24: 25.831825 | Z24: 9.7547442 | AA24: 0 | AB24: 39.798173 | AC24: 27.567755 | AD24: 25.723329 | AE24: 22.655862 | AI24: {=MAX(_xlfn._xlws.FILTER($D24:$AF24, $D$2:$AF$2=AI$2))} -> 41.090257 | AJ24: {=MAX(_xlfn._xlws.FILTER($B24:$AF24, $B$2:$AF$2=AJ$2))} -> 28.780934 | AK24: {=MAX(_xlfn._xlws.FILTER($B24:$AF24, $B$2:$AF$2=AK$2))} -> 30.694402 | AL24: {=MAX(_xlfn._xlws.FILTER($B24:$AF24, $B$2:$AF$2=AL$2))} -> 27.607208 | AM24: {=MAX(_xlfn._xlws.FILTER($B24:$AF24, $B$2:$AF$2=AM$2))} -> 28.702028 | AN24: {=MAX(_xlfn._xlws.FILTER($B24:$AF24, $B$2:$AF$2=AN$2))} -> 10.56353 | AO24: {=MAX(_xlfn._xlws.FILTER($B24:$AF24, $B$2:$AF$2=AO$2))} -> 0
A25: 11:00 AM | B25: 41.031078 | C25: 36.257269 | D25: 37.026602 | E25: 12.713716 | F25: 0 | G25: 54.09987 | H25: 37.647986 | I25: 37.62826 | J25: 33.79146 | K25: 33.337751 | L25: 12.289597 | M25: 0 | N25: 51.042266 | O25: 36.454534 | P25: 36.780021 | Q25: 33.377203 | R25: 32.519102 | S25: 11.865477 | T25: 0 | U25: 51.476249 | V25: 35.655612 | W25: 37.204141 | X25: 33.79146 | Y25: 33.337751 | Z25: 11.865477 | AA25: 0 | AB25: 52.354077 | AC25: 35.655612 | AD25: 34.649561 | AE25: 29.688352 | AI25: {=MAX(_xlfn._xlws.FILTER($D25:$AF25, $D$2:$AF$2=AI$2))} -> 54.09987 | AJ25: {=MAX(_xlfn._xlws.FILTER($B25:$AF25, $B$2:$AF$2=AJ$2))} -> 37.647986 | AK25: {=MAX(_xlfn._xlws.FILTER($B25:$AF25, $B$2:$AF$2=AK$2))} -> 41.031078 | AL25: {=MAX(_xlfn._xlws.FILTER($B25:$AF25, $B$2:$AF$2=AL$2))} -> 36.257269 | AM25: {=MAX(_xlfn._xlws.FILTER($B25:$AF25, $B$2:$AF$2=AM$2))} -> 37.026602 | AN25: {=MAX(_xlfn._xlws.FILTER($B25:$AF25, $B$2:$AF$2=AN$2))} -> 12.713716 | AO25: {=MAX(_xlfn._xlws.FILTER($B25:$AF25, $B$2:$AF$2=AO$2))} -> 0
A26: 11:30 AM | B26: 50.726642 | C26: 44.877741 | D26: 45.686527 | E26: 14.489099 | F26: 0 | G26: 66.951672 | H26: 46.42627 | I26: 46.248731 | J26: 41.810274 | K26: 40.873266 | L26: 14.055117 | M26: 0 | N26: 62.720342 | O26: 44.749519 | P26: 45.804886 | Q26: 41.366428 | R26: 39.995437 | S26: 14.055117 | T26: 0 | U26: 63.193777 | V26: 44.335263 | W26: 45.804886 | X26: 41.810274 | Y26: 40.873266 | Z26: 13.621134 | AA26: 0 | AB26: 64.604221 | AC26: 44.335263 | AD26: 42.668375 | AE26: 36.543303 | AI26: {=MAX(_xlfn._xlws.FILTER($D26:$AF26, $D$2:$AF$2=AI$2))} -> 66.951672 | AJ26: {=MAX(_xlfn._xlws.FILTER($B26:$AF26, $B$2:$AF$2=AJ$2))} -> 46.42627 | AK26: {=MAX(_xlfn._xlws.FILTER($B26:$AF26, $B$2:$AF$2=AK$2))} -> 50.726642 | AL26: {=MAX(_xlfn._xlws.FILTER($B26:$AF26, $B$2:$AF$2=AL$2))} -> 44.877741 | AM26: {=MAX(_xlfn._xlws.FILTER($B26:$AF26, $B$2:$AF$2=AM$2))} -> 45.686527 | AN26: {=MAX(_xlfn._xlws.FILTER($B26:$AF26, $B$2:$AF$2=AN$2))} -> 14.489099 | AO26: {=MAX(_xlfn._xlws.FILTER($B26:$AF26, $B$2:$AF$2=AO$2))} -> 0
A27: 12:00 PM | B27: 55.352502 | C27: 48.724405 | D27: 51.387479 | E27: 17.714379 | F27: 0 | G27: 74.753494 | H27: 51.249394 | I27: 49.878404 | J27: 45.134185 | K27: 46.406543 | L27: 16.83655 | M27: 0 | N27: 70.255857 | O27: 49.493737 | P27: 49.424695 | Q27: 45.134185 | R27: 45.045416 | S27: 16.83655 | T27: 0 | U27: 70.749019 | V27: 48.615909 | W27: 49.878404 | X27: 45.134185 | Y27: 46.406543 | Z27: 16.83655 | AA27: 0 | AB27: 72.248232 | AC27: 49.049892 | AD27: 46.229005 | AE27: 39.72913 | AI27: {=MAX(_xlfn._xlws.FILTER($D27:$AF27, $D$2:$AF$2=AI$2))} -> 74.753494 | AJ27: {=MAX(_xlfn._xlws.FILTER($B27:$AF27, $B$2:$AF$2=AJ$2))} -> 51.249394 | AK27: {=MAX(_xlfn._xlws.FILTER($B27:$AF27, $B$2:$AF$2=AK$2))} -> 55.352502 | AL27: {=MAX(_xlfn._xlws.FILTER($B27:$AF27, $B$2:$AF$2=AL$2))} -> 48.724405 | AM27: {=MAX(_xlfn._xlws.FILTER($B27:$AF27, $B$2:$AF$2=AM$2))} -> 51.387479 | AN27: {=MAX(_xlfn._xlws.FILTER($B27:$AF27, $B$2:$AF$2=AN$2))} -> 17.714379 | AO27: {=MAX(_xlfn._xlws.FILTER($B27:$AF27, $B$2:$AF$2=AO$2))} -> 0
A28: 12:30 PM | B28: 59.741643 | C28: 52.827512 | D28: 55.490587 | E28: 22.014751 | F28: 0 | G28: 77.69274 | H28: 54.671938 | I28: 53.981511 | J28: 49.53319 | K28: 49.86854 | L28: 21.087607 | M28: 0 | N28: 73.175376 | O28: 52.837376 | P28: 53.498213 | Q28: 49.069618 | R28: 48.458097 | S28: 20.624034 | T28: 0 | U28: 73.678401 | V28: 51.929958 | W28: 53.498213 | X28: 49.069618 | Y28: 49.86854 | Z28: 20.624034 | AA28: 0 | AB28: 75.187477 | AC28: 52.383667 | AD28: 50.134848 | AE28: 43.417982 | AI28: {=MAX(_xlfn._xlws.FILTER($D28:$AF28, $D$2:$AF$2=AI$2))} -> 77.69274 | AJ28: {=MAX(_xlfn._xlws.FILTER($B28:$AF28, $B$2:$AF$2=AJ$2))} -> 54.671938 | AK28: {=MAX(_xlfn._xlws.FILTER($B28:$AF28, $B$2:$AF$2=AK$2))} -> 59.741643 | AL28: {=MAX(_xlfn._xlws.FILTER($B28:$AF28, $B$2:$AF$2=AL$2))} -> 52.827512 | AM28: {=MAX(_xlfn._xlws.FILTER($B28:$AF28, $B$2:$AF$2=AM$2))} -> 55.490587 | AN28: {=MAX(_xlfn._xlws.FILTER($B28:$AF28, $B$2:$AF$2=AN$2))} -> 22.014751 | AO28: {=MAX(_xlfn._xlws.FILTER($B28:$AF28, $B$2:$AF$2=AO$2))} -> 0
A29: 1:00 PM | B29: 62.878154 | C29: 56.693902 | D29: 59.307661 | E29: 24.766595 | F29: 0 | G29: 79.981012 | H29: 59.287934 | I29: 56.861577 | J29: 52.304761 | K29: 53.439033 | L29: 23.287109 | M29: 0 | N29: 75.414331 | O29: 56.891167 | P29: 56.358552 | Q29: 52.304761 | R29: 51.979274 | S29: 23.287109 | T29: 0 | U29: 75.92722 | V29: 56.407868 | W29: 56.861577 | X29: 52.304761 | Y29: 52.955734 | Z29: 22.80381 | AA29: 0 | AB29: 77.446159 | AC29: 56.407868 | AD29: 52.847239 | AE29: 45.962697 | AI29: {=MAX(_xlfn._xlws.FILTER($D29:$AF29, $D$2:$AF$2=AI$2))} -> 79.981012 | AJ29: {=MAX(_xlfn._xlws.FILTER($B29:$AF29, $B$2:$AF$2=AJ$2))} -> 59.287934 | AK29: {=MAX(_xlfn._xlws.FILTER($B29:$AF29, $B$2:$AF$2=AK$2))} -> 62.878154 | AL29: {=MAX(_xlfn._xlws.FILTER($B29:$AF29, $B$2:$AF$2=AL$2))} -> 56.693902 | AM29: {=MAX(_xlfn._xlws.FILTER($B29:$AF29, $B$2:$AF$2=AM$2))} -> 59.307661 | AN29: {=MAX(_xlfn._xlws.FILTER($B29:$AF29, $B$2:$AF$2=AN$2))} -> 24.766595 | AO29: {=MAX(_xlfn._xlws.FILTER($B29:$AF29, $B$2:$AF$2=AO$2))} -> 0
A30: 1:30 PM | B30: 64.909981 | C30: 59.593695 | D30: 61.595933 | E30: 24.697552 | F30: 0 | G30: 81.884617 | H30: 62.187727 | I30: 58.883542 | J30: 55.174963 | K30: 55.648399 | L30: 23.19834 | M30: 0 | N30: 76.745869 | O30: 60.215079 | P30: 58.380516 | Q30: 54.681801 | R30: 53.665888 | S30: 23.19834 | T30: 0 | U30: 77.781509 | V30: 59.238618 | W30: 58.380516 | X30: 55.174963 | Y30: 55.155237 | Z30: 22.695315 | AA30: 0 | AB30: 79.320174 | AC30: 59.238618 | AD30: 54.366178 | AE30: 48.290422 | AI30: {=MAX(_xlfn._xlws.FILTER($D30:$AF30, $D$2:$AF$2=AI$2))} -> 81.884617 | AJ30: {=MAX(_xlfn._xlws.FILTER($B30:$AF30, $B$2:$AF$2=AJ$2))} -> 62.187727 | AK30: {=MAX(_xlfn._xlws.FILTER($B30:$AF30, $B$2:$AF$2=AK$2))} -> 64.909981 | AL30: {=MAX(_xlfn._xlws.FILTER($B30:$AF30, $B$2:$AF$2=AL$2))} -> 59.593695 | AM30: {=MAX(_xlfn._xlws.FILTER($B30:$AF30, $B$2:$AF$2=AM$2))} -> 61.595933 | AN30: {=MAX(_xlfn._xlws.FILTER($B30:$AF30, $B$2:$AF$2=AN$2))} -> 24.697552 | AO30: {=MAX(_xlfn._xlws.FILTER($B30:$AF30, $B$2:$AF$2=AO$2))} -> 0
... A48: 10:30 PM | B48: 7.0916694 | C48: 6.3716529 | D48: 5.4543716 | E48: 0 | F48: 0 | G48: 7.0818062 | H48: 7.446746 | I48: 6.5590545 | J48: 5.8982174 | K48: 4.9710729 | L48: 0 | M48: 0 | N48: 6.5590545 | O48: 7.446746 | P48: 6.5590545 | Q48: 5.8982174 | R48: 4.9710729 | S48: 0 | T48: 0 | U48: 6.5590545 | V48: 7.446746 | W48: 6.5590545 | X48: 5.8982174 | Y48: 4.9710729 | Z48: 0 | AA48: 0 | AB48: 7.0818062 | AC48: 7.446746 | AD48: 6.0264395 | AE48: 4.9513464 | AI48: {=MAX(_xlfn._xlws.FILTER($D48:$AF48, $D$2:$AF$2=AI$2))} -> 7.0818062 | AJ48: {=MAX(_xlfn._xlws.FILTER($B48:$AF48, $B$2:$AF$2=AJ$2))} -> 7.446746 | AK48: {=MAX(_xlfn._xlws.FILTER($B48:$AF48, $B$2:$AF$2=AK$2))} -> 7.0916694 | AL48: {=MAX(_xlfn._xlws.FILTER($B48:$AF48, $B$2:$AF$2=AL$2))} -> 6.3716529 | AM48: {=MAX(_xlfn._xlws.FILTER($B48:$AF48, $B$2:$AF$2=AM$2))} -> 5.4543716 | AN48: {=MAX(_xlfn._xlws.FILTER($B48:$AF48, $B$2:$AF$2=AN$2))} -> 0 | AO48: {=MAX(_xlfn._xlws.FILTER($B48:$AF48, $B$2:$AF$2=AO$2))} -> 0
A49: 11:00 PM | AI49: {=MAX(_xlfn._xlws.FILTER($D49:$AF49, $D$2:$AF$2=AI$2))} -> 0 | AJ49: {=MAX(_xlfn._xlws.FILTER($B49:$AF49, $B$2:$AF$2=AJ$2))} -> 0 | AK49: {=MAX(_xlfn._xlws.FILTER($B49:$AF49, $B$2:$AF$2=AK$2))} -> 0 | AL49: {=MAX(_xlfn._xlws.FILTER($B49:$AF49, $B$2:$AF$2=AL$2))} -> 0 | AM49: {=MAX(_xlfn._xlws.FILTER($B49:$AF49, $B$2:$AF$2=AM$2))} -> 0 | AN49: {=MAX(_xlfn._xlws.FILTER($B49:$AF49, $B$2:$AF$2=AN$2))} -> 0 | AO49: {=MAX(_xlfn._xlws.FILTER($B49:$AF49, $B$2:$AF$2=AO$2))} -> 0
A50: 11:30 PM | AI50: {=MAX(_xlfn._xlws.FILTER($D50:$AF50, $D$2:$AF$2=AI$2))} -> 0 | AJ50: {=MAX(_xlfn._xlws.FILTER($B50:$AF50, $B$2:$AF$2=AJ$2))} -> 0 | AK50: {=MAX(_xlfn._xlws.FILTER($B50:$AF50, $B$2:$AF$2=AK$2))} -> 0 | AL50: {=MAX(_xlfn._xlws.FILTER($B50:$AF50, $B$2:$AF$2=AL$2))} -> 0 | AM50: {=MAX(_xlfn._xlws.FILTER($B50:$AF50, $B$2:$AF$2=AM$2))} -> 0 | AN50: {=MAX(_xlfn._xlws.FILTER($B50:$AF50, $B$2:$AF$2=AN$2))} -> 0 | AO50: {=MAX(_xlfn._xlws.FILTER($B50:$AF50, $B$2:$AF$2=AO$2))} -> 0
B51: =MAX(B3:B50) -> 67.553329 | C51: =MAX(C3:C50) -> 60.09672 | D51: =MAX(D3:D50) -> 62.365265 | E51: =MAX(E3:E50) -> 24.766595 | F51: =MAX(F3:F50) -> 0 | G51: =MAX(G3:G50) -> 81.884617 | H51: =MAX(H3:H50) -> 62.976786 | I51: =MAX(I3:I50) -> 61.378941 | ... AF51: =MAX(AF3:AF50) -> 0

Sheet V-Vol Apr
A1: Row Labels | B1: ='V-FTE Apr'!B1 -> 46113 | C1: ='V-FTE Apr'!C1 -> 46114 | D1: ='V-FTE Apr'!D1 -> 46115 | E1: ='V-FTE Apr'!E1 -> 46116 | F1: ='V-FTE Apr'!F1 -> 46117 | G1: ='V-FTE Apr'!G1 -> 46118 | H1: ='V-FTE Apr'!H1 -> 46119 | I1: ='V-FTE Apr'!I1 -> 46120 | ... AF1: ='V-FTE Apr'!AF1 -> 46143
B2: =TEXT(B1,"ddd") -> Wed | C2: =TEXT(C1,"ddd") -> Thu | D2: =TEXT(D1,"ddd") -> Fri | E2: =TEXT(E1,"ddd") -> Sat | F2: =TEXT(F1,"ddd") -> Sun | G2: =TEXT(G1,"ddd") -> Mon | H2: =TEXT(H1,"ddd") -> Tue | I2: =TEXT(I1,"ddd") -> Wed | ... AF2: =TEXT(AF1,"ddd") -> Fri
A3: 0.020833333 | B3: 0 | C3: 0 | D3: 0 | E3: 0 | F3: 0 | G3: 0 | H3: 0 | I3: 0 | J3: 0 | K3: 0 | L3: 0 | M3: 0 | N3: 0 | O3: 0 | P3: 0 | Q3: 0 | R3: 0 | S3: 0 | T3: 0 | U3: 0 | V3: 0 | W3: 0 | X3: 0 | Y3: 0 | Z3: 0 | AA3: 0 | AB3: 0 | AC3: 0 | AD3: 0 | AE3: 0 | AF3: 0
A4: 0.041666667 | B4: 0 | C4: 0 | D4: 0 | E4: 0 | F4: 0 | G4: 0 | H4: 0 | I4: 0 | J4: 0 | K4: 0 | L4: 0 | M4: 0 | N4: 0 | O4: 0 | P4: 0 | Q4: 0 | R4: 0 | S4: 0 | T4: 0 | U4: 0 | V4: 0 | W4: 0 | X4: 0 | Y4: 0 | Z4: 0 | AA4: 0 | AB4: 0 | AC4: 0 | AD4: 0 | AE4: 0 | AF4: 0
A5: 0.0625 | B5: 0 | C5: 0 | D5: 0 | E5: 0 | F5: 0 | G5: 0 | H5: 0 | I5: 0 | J5: 0 | K5: 0 | L5: 0 | M5: 0 | N5: 0 | O5: 0 | P5: 0 | Q5: 0 | R5: 0 | S5: 0 | T5: 0 | U5: 0 | V5: 0 | W5: 0 | X5: 0 | Y5: 0 | Z5: 0 | AA5: 0 | AB5: 0 | AC5: 0 | AD5: 0 | AE5: 0 | AF5: 0
A6: 0.083333333 | B6: 0 | C6: 0 | D6: 0 | E6: 0 | F6: 0 | G6: 0 | H6: 0 | I6: 0 | J6: 0 | K6: 0 | L6: 0 | M6: 0 | N6: 0 | O6: 0 | P6: 0 | Q6: 0 | R6: 0 | S6: 0 | T6: 0 | U6: 0 | V6: 0 | W6: 0 | X6: 0 | Y6: 0 | Z6: 0 | AA6: 0 | AB6: 0 | AC6: 0 | AD6: 0 | AE6: 0 | AF6: 0
A7: 0.10416667 | B7: 0 | C7: 0 | D7: 0 | E7: 0 | F7: 0 | G7: 0 | H7: 0 | I7: 0 | J7: 0 | K7: 0 | L7: 0 | M7: 0 | N7: 0 | O7: 0 | P7: 0 | Q7: 0 | R7: 0 | S7: 0 | T7: 0 | U7: 0 | V7: 0 | W7: 0 | X7: 0 | Y7: 0 | Z7: 0 | AA7: 0 | AB7: 0 | AC7: 0 | AD7: 0 | AE7: 0 | AF7: 0
A8: 0.125 | B8: 0 | C8: 0 | D8: 0 | E8: 0 | F8: 0 | G8: 0 | H8: 0 | I8: 0 | J8: 0 | K8: 0 | L8: 0 | M8: 0 | N8: 0 | O8: 0 | P8: 0 | Q8: 0 | R8: 0 | S8: 0 | T8: 0 | U8: 0 | V8: 0 | W8: 0 | X8: 0 | Y8: 0 | Z8: 0 | AA8: 0 | AB8: 0 | AC8: 0 | AD8: 0 | AE8: 0 | AF8: 0
A9: 0.14583333 | B9: 0 | C9: 0 | D9: 0 | E9: 0 | F9: 0 | G9: 0 | H9: 0 | I9: 0 | J9: 0 | K9: 0 | L9: 0 | M9: 0 | N9: 0 | O9: 0 | P9: 0 | Q9: 0 | R9: 0 | S9: 0 | T9: 0 | U9: 0 | V9: 0 | W9: 0 | X9: 0 | Y9: 0 | Z9: 0 | AA9: 0 | AB9: 0 | AC9: 0 | AD9: 0 | AE9: 0 | AF9: 0
A10: 0.16666667 | B10: 0 | C10: 0 | D10: 0 | E10: 0 | F10: 0 | G10: 0 | H10: 0 | I10: 0 | J10: 0 | K10: 0 | L10: 0 | M10: 0 | N10: 0 | O10: 0 | P10: 0 | Q10: 0 | R10: 0 | S10: 0 | T10: 0 | U10: 0 | V10: 0 | W10: 0 | X10: 0 | Y10: 0 | Z10: 0 | AA10: 0 | AB10: 0 | AC10: 0 | AD10: 0 | AE10: 0 | AF10: 0
A11: 0.1875 | B11: 0 | C11: 0 | D11: 0 | E11: 0 | F11: 0 | G11: 0 | H11: 0 | I11: 0 | J11: 0 | K11: 0 | L11: 0 | M11: 0 | N11: 0 | O11: 0 | P11: 0 | Q11: 0 | R11: 0 | S11: 0 | T11: 0 | U11: 0 | V11: 0 | W11: 0 | X11: 0 | Y11: 0 | Z11: 0 | AA11: 0 | AB11: 0 | AC11: 0 | AD11: 0 | AE11: 0 | AF11: 0
A12: 0.20833333 | B12: 0 | C12: 0 | D12: 0 | E12: 0 | F12: 0 | G12: 0 | H12: 0 | I12: 0 | J12: 0 | K12: 0 | L12: 0 | M12: 0 | N12: 0 | O12: 0 | P12: 0 | Q12: 0 | R12: 0 | S12: 0 | T12: 0 | U12: 0 | V12: 0 | W12: 0 | X12: 0 | Y12: 0 | Z12: 0 | AA12: 0 | AB12: 0 | AC12: 0 | AD12: 0 | AE12: 0 | AF12: 0
A13: 0.22916667 | B13: 0 | C13: 0 | D13: 0 | E13: 0 | F13: 0 | G13: 0 | H13: 0 | I13: 0 | J13: 0 | K13: 0 | L13: 0 | M13: 0 | N13: 0 | O13: 0 | P13: 0 | Q13: 0 | R13: 0 | S13: 0 | T13: 0 | U13: 0 | V13: 0 | W13: 0 | X13: 0 | Y13: 0 | Z13: 0 | AA13: 0 | AB13: 0 | AC13: 0 | AD13: 0 | AE13: 0 | AF13: 0
A14: 0.25 | B14: 0 | C14: 0 | D14: 0 | E14: 0 | F14: 0 | G14: 0 | H14: 0 | I14: 0 | J14: 0 | K14: 0 | L14: 0 | M14: 0 | N14: 0 | O14: 0 | P14: 0 | Q14: 0 | R14: 0 | S14: 0 | T14: 0 | U14: 0 | V14: 0 | W14: 0 | X14: 0 | Y14: 0 | Z14: 0 | AA14: 0 | AB14: 0 | AC14: 0 | AD14: 0 | AE14: 0 | AF14: 0
... A17: 0.3125 | B17: 0 | C17: 0 | D17: 0 | E17: 0 | F17: 0 | G17: 0 | H17: 0 | I17: 0 | J17: 0 | K17: 0 | L17: 0 | M17: 0 | N17: 0 | O17: 0 | P17: 0 | Q17: 0 | R17: 0 | S17: 0 | T17: 0 | U17: 0 | V17: 0 | W17: 0 | X17: 0 | Y17: 0 | Z17: 0 | AA17: 0 | AB17: 0 | AC17: 0 | AD17: 0 | AE17: 0 | AF17: 0
A18: 0.33333333 | B18: 9 | C18: 9 | D18: 10 | E18: 0 | F18: 0 | G18: 14 | H18: 9 | I18: 8 | J18: 8 | K18: 9 | L18: 0 | M18: 0 | N18: 13 | O18: 8 | P18: 8 | Q18: 8 | R18: 8 | S18: 0 | T18: 0 | U18: 13 | V18: 8 | W18: 8 | X18: 8 | Y18: 9 | Z18: 0 | AA18: 0 | AB18: 14 | AC18: 8 | AD18: 8 | AE18: 7
A19: 0.35416667 | B19: 17 | C19: 16 | D19: 16 | E19: 0 | F19: 0 | G19: 23 | H19: 16 | I19: 16 | J19: 15 | K19: 15 | L19: 0 | M19: 0 | N19: 21 | O19: 15 | P19: 16 | Q19: 15 | R19: 14 | S19: 0 | T19: 0 | U19: 22 | V19: 15 | W19: 16 | X19: 15 | Y19: 15 | Z19: 0 | AA19: 0 | AB19: 22 | AC19: 15 | AD19: 14 | AE19: 13
A20: 0.375 | B20: 30 | C20: 29 | D20: 29 | E20: 8 | F20: 0 | G20: 41 | H20: 29 | I20: 27 | J20: 27 | K20: 26 | L20: 8 | M20: 0 | N20: 38 | O20: 28 | P20: 27 | Q20: 26 | R20: 26 | S20: 7 | T20: 0 | U20: 39 | V20: 27 | W20: 27 | X20: 26 | Y20: 26 | Z20: 7 | AA20: 0 | AB20: 40 | AC20: 27 | AD20: 25 | AE20: 23
A21: 0.39583333 | B21: 44 | C21: 41 | D21: 43 | E21: 12 | F21: 0 | G21: 60 | H21: 42 | I21: 39 | J21: 38 | K21: 39 | L21: 11 | M21: 0 | N21: 57 | O21: 41 | P21: 39 | Q21: 38 | R21: 38 | S21: 11 | T21: 0 | U21: 57 | V21: 40 | W21: 39 | X21: 38 | Y21: 39 | Z21: 11 | AA21: 0 | AB21: 58 | AC21: 40 | AD21: 36 | AE21: 33
A22: 0.41666667 | B22: 57 | C22: 52 | D22: 54 | E22: 18 | F22: 0 | G22: 75 | H22: 54 | I22: 52 | J22: 48 | K22: 49 | L22: 17 | M22: 0 | N22: 71 | O22: 52 | P22: 51 | Q22: 47 | R22: 47 | S22: 17 | T22: 0 | U22: 71 | V22: 51 | W22: 51 | X22: 48 | Y22: 48 | Z22: 17 | AA22: 0 | AB22: 73 | AC22: 52 | AD22: 48 | AE22: 41
A23: 0.4375 | B23: 71 | C23: 64 | D23: 67 | E23: 24 | F23: 0 | G23: 92 | H23: 68 | I23: 64 | J23: 59 | K23: 60 | L23: 23 | M23: 0 | N23: 87 | O23: 66 | P23: 63 | Q23: 59 | R23: 58 | S23: 23 | T23: 0 | U23: 87 | V23: 65 | W23: 64 | X23: 59 | Y23: 60 | Z23: 22 | AA23: 0 | AB23: 89 | AC23: 65 | AD23: 59 | AE23: 52
A24: 0.45833333 | B24: 93 | C24: 85 | D24: 87 | E24: 28 | F24: 0 | G24: 120 | H24: 91 | I24: 85 | J24: 79 | K24: 78 | L24: 27 | M24: 0 | N24: 113 | O24: 88 | P24: 83 | Q24: 78 | R24: 76 | S24: 26 | T24: 0 | U24: 114 | V24: 86 | W24: 84 | X24: 79 | Y24: 78 | Z24: 26 | AA24: 0 | AB24: 116 | AC24: 86 | AD24: 78 | AE24: 69
A25: 0.47916667 | B25: 110 | C25: 99 | D25: 101 | E25: 31 | F25: 0 | G25: 139 | H25: 107 | I25: 100 | J25: 92 | K25: 90 | L25: 30 | M25: 0 | N25: 130 | O25: 103 | P25: 99 | Q25: 91 | R25: 88 | S25: 30 | T25: 0 | U25: 131 | V25: 102 | W25: 99 | X25: 92 | Y25: 90 | Z25: 29 | AA25: 0 | AB25: 134 | AC25: 102 | AD25: 92 | AE25: 80
A26: 0.5 | B26: 118 | C26: 105 | D26: 110 | E26: 38 | F26: 0 | G26: 146 | H26: 113 | I26: 106 | J26: 97 | K26: 99 | L26: 36 | M26: 0 | N26: 137 | O26: 109 | P26: 105 | Q26: 97 | R26: 96 | S26: 36 | T26: 0 | U26: 138 | V26: 107 | W26: 106 | X26: 97 | Y26: 99 | Z26: 36 | AA26: 0 | AB26: 141 | AC26: 108 | AD26: 98 | AE26: 85
A27: 0.52083333 | B27: 121 | C27: 109 | D27: 115 | E27: 45 | F27: 0 | G27: 151 | H27: 116 | I27: 109 | J27: 102 | K27: 103 | L27: 43 | M27: 0 | N27: 142 | O27: 112 | P27: 108 | Q27: 101 | R27: 100 | S27: 42 | T27: 0 | U27: 143 | V27: 110 | W27: 108 | X27: 101 | Y27: 103 | Z27: 42 | AA27: 0 | AB27: 146 | AC27: 111 | AD27: 101 | AE27: 89
A28: 0.54166667 | B28: 122 | C28: 113 | D28: 118 | E28: 48 | F28: 0 | G28: 154 | H28: 120 | I28: 110 | J28: 104 | K28: 106 | L28: 45 | M28: 0 | N28: 145 | O28: 115 | P28: 109 | Q28: 104 | R28: 103 | S28: 45 | T28: 0 | U28: 146 | V28: 114 | W28: 110 | X28: 104 | Y28: 105 | Z28: 44 | AA28: 0 | AB28: 149 | AC28: 114 | AD28: 102 | AE28: 91
A29: 0.5625 | B29: 126 | C29: 118 | D29: 121 | E29: 47 | F29: 0 | G29: 156 | H29: 123 | I29: 114 | J29: 109 | K29: 109 | L29: 44 | M29: 0 | N29: 146 | O29: 119 | P29: 113 | Q29: 108 | R29: 105 | S29: 44 | T29: 0 | U29: 148 | V29: 117 | W29: 113 | X29: 109 | Y29: 108 | Z29: 43 | AA29: 0 | AB29: 151 | AC29: 117 | AD29: 105 | AE29: 95
... A49: 0.97916667 | B49: 0 | C49: 0 | D49: 0 | E49: 0 | F49: 0 | G49: 0 | H49: 0 | I49: 0 | J49: 0 | K49: 0 | L49: 0 | M49: 0 | N49: 0 | O49: 0 | P49: 0 | Q49: 0 | R49: 0 | S49: 0 | T49: 0 | U49: 0 | V49: 0 | W49: 0 | X49: 0 | Y49: 0 | Z49: 0 | AA49: 0 | AB49: 0 | AC49: 0 | AD49: 0 | AE49: 0
A50: Volume | B50: =SUM(B2:B49) -> 2425 | C50: =SUM(C2:C49) -> 2207 | D50: =SUM(D2:D49) -> 2251 | E50: =SUM(E2:E49) -> 777 | F50: =SUM(F2:F49) -> 0 | G50: =SUM(G2:G49) -> 2889 | H50: =SUM(H2:H49) -> 2387 | I50: =SUM(I2:I49) -> 2196 | ... AF50: =SUM(AF2:AF49) -> 0 | AG50: =SUM(B50:AF50) -> 52674

Sheet V-Hrs Apr
A1: Row Labels | B1: ='V-FTE Apr'!B1 -> 46113 | C1: ='V-FTE Apr'!C1 -> 46114 | D1: ='V-FTE Apr'!D1 -> 46115 | E1: ='V-FTE Apr'!E1 -> 46116 | F1: ='V-FTE Apr'!F1 -> 46117 | G1: ='V-FTE Apr'!G1 -> 46118 | H1: ='V-FTE Apr'!H1 -> 46119 | I1: ='V-FTE Apr'!I1 -> 46120 | ... AF1: ='V-FTE Apr'!AF1 -> 46143
B2: =TEXT(B1,"ddd") -> Wed | C2: =TEXT(C1,"ddd") -> Thu | D2: =TEXT(D1,"ddd") -> Fri | E2: =TEXT(E1,"ddd") -> Sat | F2: =TEXT(F1,"ddd") -> Sun | G2: =TEXT(G1,"ddd") -> Mon | H2: =TEXT(H1,"ddd") -> Tue | I2: =TEXT(I1,"ddd") -> Wed | ... AF2: =TEXT(AF1,"ddd") -> Fri
A3: 12:00 AM | B3: ='V-FTE Mar'!B3/2 -> 0 | C3: ='V-FTE Mar'!C3/2 -> 0 | D3: ='V-FTE Mar'!D3/2 -> 0 | E3: ='V-FTE Mar'!E3/2 -> 0 | F3: ='V-FTE Mar'!F3/2 -> 0 | G3: ='V-FTE Mar'!G3/2 -> 0 | H3: ='V-FTE Mar'!H3/2 -> 0 | I3: ='V-FTE Mar'!I3/2 -> 0 | ... AE3: ='V-FTE Mar'!AE3/2 -> 0
A4: 12:30 AM | B4: ='V-FTE Mar'!B4/2 -> 0 | C4: ='V-FTE Mar'!C4/2 -> 0 | D4: ='V-FTE Mar'!D4/2 -> 0 | E4: ='V-FTE Mar'!E4/2 -> 0 | F4: ='V-FTE Mar'!F4/2 -> 0 | G4: ='V-FTE Mar'!G4/2 -> 0 | H4: ='V-FTE Mar'!H4/2 -> 0 | I4: ='V-FTE Mar'!I4/2 -> 0 | ... AE4: ='V-FTE Mar'!AE4/2 -> 0
